Workbook

Sheet Terminologies

Sheet Instructions
A1: Sr No | B1: Particulars
A2: 1 | B2: Each Region will have a unique Area Name, OLT ID & Cluster ID.
A3: =A2+1 -> 2 | B3: Every FAT/OLD/FDC/JC will have a unique ID.
A4: =A3+1 -> 3 | B4: Each entity as mentioned in above pt, will have a separate row & respective entry in the tracker | R4: Item Name
A5: =A4+1 -> 4 | B5: Kindly refer Terminologies sheet for model understanding. Alternatively you can also use respective SLDs for the same | R5: FDC
A6: =A5+1 -> 5 | B6: For filling the trackers, regional teams will have to fill cells where Headings are not highlighted. | R6: FAT Box
A7: =A6+1 -> 6 | B7: Central Team will be filling data for cells where Headings are highlighted in Yellow | R7: Duct
A8: =A7+1 -> 7 | B8: Kindly do not fill any cell where headings are highlighted in Green. | R8: Primary Splitter
A9: =A8+1 -> 8 | B9: For all FAT/FDC there will be an entry of separate row in "Node Details" sheet.
A10: =A9+1 -> 9 | B10: Any extension of current path,route will be treated as a new route.
A11: =A10+1 -> 10 | B11: Any new branch getting deployed from same common FAT/FDC which is not part of existing route shall be treated as a New Route.
A12: =A11+1 -> 11 | B12: Fiber Material & Fiber Execution service details are to be entered in "Route Details" & "Node Details" sheet only.
A13: =A12+1 -> 12 | B13: Tracker has to be filled all routes that are RFS/Deployed irrespective of Sign-off.
A14: =A13+1 -> 13 | B14: Billing start date will be HOTO date, when penetration % is >=50% | R14: Secondary Splitter
A15: =A14+1 -> 14 | B15: Kindly enter date in DD_MMM_YYYY format for all columns where date has to be entered. | R15: Pigtail
A16: =A15+1 -> 15 | B16: Kindly do not alter format of the sheet, i.e add or delete rows/columns or do any formatting changes. | R16: Patch Cords
R17: Tiffin Box
R18: FMS

Sheet Route-Details
O1: =SUBTOTAL(9,O3:O1048576) -> 7827 | W1: =SUBTOTAL(9,W3:W1048576) -> 7827 | X1: =SUBTOTAL(9,X3:X1048576) -> 7827 | AE1: =SUBTOTAL(9,AE3:AE1048576) -> 7827 | AL1: =SUBTOTAL(9,AL3:AL1048576) -> 7827 | BB1: =SUBTOTAL(9,BB3:BB1048576) -> 7827 | BC1: =SUBTOTAL(9,BC3:BC1048576) -> 156540
A2: Sr No | B2: Unique Route ID | C2: FDC/FAT Unique ID (Start Point) | D2: Start point Latlong | E2: FDC/FAT Unique ID (End Point) | F2: End point Latlong | G2: Customer | H2: Area Name | I2: City | J2: Telecom Circle | K2: State | L2: OLT ID | M2: Cluster ID | N2: Online AT Date (Delivered) | O2: Online AT Length (Delivered) | P2: HOTO Date | Q2: HOTO Signoff Date | R2: Start Date (Date from which we can bill) | S2: Lock-in Period | T2: Surrender Date | U2: Fresh Delivery/Renewal | V2: Fiber Capacity | W2: OTDR length (in meters) | X2: Customer Billable length (in meters) | Z2: Customer PO no | AA2: PO length | AB2: PO Date | AC2: PO Rate | AE2: Fiber length deployed/used (in meters) | AF2: Fiber Type | AG2: Fiber Capacity | AH2: Fiber Rate per meter (incl Freight) | AI2: Fiber Material Cost | AK2: Execution Vendor Name | AL2: Vendor Billable Length (Fiber laying) | AM2: Fiber Laying Rate | AN2: Fiber Laying/Execution Cost | AO2: OTM Length | AP2: OTM Execution Rate | AQ2: OTM Cost | AR2: Total Vendor Cost | AT2: Vendor PO No | AU2: Vendor PO Date | AV2: Vendor PO Rate | AW2: Vendor PO Cost | AY2: Vendor Invoice No | AZ2: Vendor Invoice Date | BA2: Vendor Invoice Rate | BB2: Vendor Invoiced length | BC2: Invoice Amt
A3: 1 | B3: 0000001GF-00001GF12 | C3: 1GF | D3: R-1 | E3: 1GF12 | G3: Airtel | H3: Gorai | I3: Mumbai | J3: Mumbai | K3: Maharashtra | L3: 1GF | M3: 1GF | N3: 45141 | O3: 829 | P3: 45379 | Q3: 45379 | V3: 24F | W3: =O3 -> 829 | X3: =W3 -> 829 | Z3: BAL-ANG-UASL-Mumbai-Maharashtra/PUR/100 04346 | AA3: 3500 | AB3: 45181 | AC3: 122 | AE3: =X3 -> 829 | AF3: UA | AG3: 24F | AH3: 122 | AI3: =IF(AE3<>"",AH3*AE3,0) -> 101138 | AK3: Sudhist Enterprises | AL3: =AE3 -> 829 | AM3: 20 | AN3: =IF(AL3<>"",AM3*AL3,0) -> 16580 | AQ3: =IF(AO3<>"",AP3*AO3,0) -> 0 | AR3: =AQ3+AN3 -> 16580 | AT3: ETIL-PUR-ORD-23-10-00058 | AU3: 45211 | AV3: =AM3 -> 20 | AW3: =AV3*AL3 -> 16580 | AY3: SE/361 BG | AZ3: 45257 | BA3: =AM3 -> 20 | BB3: =AL3 -> 829 | BC3: =IF(BB3<>"",BB3*BA3,0) -> 16580
A4: =IF(B4<>"",A3+1,"") -> 2 | B4: 00001GF22-0000001GF | C4: 1GF22 | D4: R-2 | E4: 1GF | G4: Airtel | H4: Gorai | I4: Mumbai | J4: Mumbai | K4: Maharashtra | L4: 1GF | M4: 1GF | N4: 45141 | O4: 800 | P4: 45379 | Q4: 45379 | V4: 24F | W4: =O4 -> 800 | X4: =W4 -> 800 | Z4: BAL-ANG-UASL-Mumbai-Maharashtra/PUR/100 04346 | AA4: 3500 | AB4: 45181 | AC4: 122 | AE4: =X4 -> 800 | AF4: UA | AG4: 24F | AH4: 122 | AI4: =IF(AE4<>"",AH4*AE4,0) -> 97600 | AK4: Sudhist Enterprises | AL4: =AE4 -> 800 | AM4: 20 | AN4: =IF(AL4<>"",AM4*AL4,0) -> 16000 | AQ4: =IF(AO4<>"",AP4*AO4,0) -> 0 | AR4: =AQ4+AN4 -> 16000 | AT4: ETIL-PUR-ORD-23-10-00058 | AU4: 45211 | AV4: =AM4 -> 20 | AW4: =AV4*AL4 -> 16000 | AY4: SE/361 BG | AZ4: 45257 | BA4: =AM4 -> 20 | BB4: =AL4 -> 800 | BC4: =IF(BB4<>"",BB4*BA4,0) -> 16000
A5: =IF(B5<>"",A4+1,"") -> 3 | B5: 00001GF12-00001GF22 | C5: 1GF12 | D5: R-3 | E5: 1GF22 | G5: Airtel | H5: Gorai | I5: Mumbai | J5: Mumbai | K5: Maharashtra | L5: 1GF | M5: 1GF | N5: 45141 | O5: 1285 | P5: 45379 | Q5: 45379 | V5: 12F | W5: =O5 -> 1285 | X5: =W5 -> 1285 | Z5: BAL-ANG-UASL-Mumbai-Maharashtra/PUR/100 04346 | AA5: 14000 | AB5: 45181 | AC5: 102 | AE5: =X5 -> 1285 | AF5: UA | AG5: 12F | AH5: 102 | AI5: =IF(AE5<>"",AH5*AE5,0) -> 131070 | AK5: Sudhist Enterprises | AL5: =AE5 -> 1285 | AM5: 20 | AN5: =IF(AL5<>"",AM5*AL5,0) -> 25700 | AQ5: =IF(AO5<>"",AP5*AO5,0) -> 0 | AR5: =AQ5+AN5 -> 25700 | AT5: ETIL-PUR-ORD-23-10-00058 | AU5: 45211 | AV5: =AM5 -> 20 | AW5: =AV5*AL5 -> 25700 | AY5: SE/361 BG | AZ5: 45257 | BA5: =AM5 -> 20 | BB5: =AL5 -> 1285 | BC5: =IF(BB5<>"",BB5*BA5,0) -> 25700
A6: =IF(B6<>"",A5+1,"") -> 4 | B6: 00001GF12-1GF120106 | C6: 1GF12 | D6: R-4 | E6: 1GF120106 | G6: Airtel | H6: Gorai | I6: Mumbai | J6: Mumbai | K6: Maharashtra | L6: 1GF | M6: 1GF | N6: 45141 | O6: 348 | P6: 45379 | Q6: 45379 | V6: 24F | W6: =O6 -> 348 | X6: =W6 -> 348 | Z6: BAL-ANG-UASL-Mumbai-Maharashtra/PUR/100 04346 | AA6: 3500 | AB6: 45181 | AC6: 122 | AE6: =X6 -> 348 | AF6: UA | AG6: 24F | AH6: 122 | AI6: =IF(AE6<>"",AH6*AE6,0) -> 42456 | AK6: Sudhist Enterprises | AL6: =AE6 -> 348 | AM6: 20 | AN6: =IF(AL6<>"",AM6*AL6,0) -> 6960 | AQ6: =IF(AO6<>"",AP6*AO6,0) -> 0 | AR6: =AQ6+AN6 -> 6960 | AT6: ETIL-PUR-ORD-23-10-00058 | AU6: 45211 | AV6: =AM6 -> 20 | AW6: =AV6*AL6 -> 6960 | AY6: SE/361 BG | AZ6: 45257 | BA6: =AM6 -> 20 | BB6: =AL6 -> 348 | BC6: =IF(BB6<>"",BB6*BA6,0) -> 6960
A7: =IF(B7<>"",A6+1,"") -> 5 | B7: 00001GF13-1GF130106 | C7: 1GF13 | D7: R-5 | E7: 1GF130106 | G7: Airtel | H7: Gorai | I7: Mumbai | J7: Mumbai | K7: Maharashtra | L7: 1GF | M7: 1GF | N7: 45141 | O7: 401 | P7: 45379 | Q7: 45379 | V7: 12F | W7: =O7 -> 401 | X7: =W7 -> 401 | Z7: BAL-ANG-UASL-Mumbai-Maharashtra/PUR/100 04346 | AA7: 14000 | AB7: 45181 | AC7: 102 | AE7: =X7 -> 401 | AF7: UA | AG7: 12F | AH7: 102 | AI7: =IF(AE7<>"",AH7*AE7,0) -> 40902 | AK7: Sudhist Enterprises | AL7: =AE7 -> 401 | AM7: 20 | AN7: =IF(AL7<>"",AM7*AL7,0) -> 8020 | AQ7: =IF(AO7<>"",AP7*AO7,0) -> 0 | AR7: =AQ7+AN7 -> 8020 | AT7: ETIL-PUR-ORD-23-10-00058 | AU7: 45211 | AV7: =AM7 -> 20 | AW7: =AV7*AL7 -> 8020 | AY7: SE/361 BG | AZ7: 45257 | BA7: =AM7 -> 20 | BB7: =AL7 -> 401 | BC7: =IF(BB7<>"",BB7*BA7,0) -> 8020
A8: =IF(B8<>"",A7+1,"") -> 6 | B8: 00001GF14-1GF140107 | C8: 1GF14 | D8: R-6 | E8: 1GF140107 | G8: Airtel | H8: Gorai | I8: Mumbai | J8: Mumbai | K8: Maharashtra | L8: 1GF | M8: 1GF | N8: 45141 | O8: 427 | P8: 45379 | Q8: 45379 | V8: 12F | W8: =O8 -> 427 | X8: =W8 -> 427 | Z8: BAL-ANG-UASL-Mumbai-Maharashtra/PUR/100 04346 | AA8: 14000 | AB8: 45181 | AC8: 102 | AE8: =X8 -> 427 | AF8: UA | AG8: 12F | AH8: 102 | AI8: =IF(AE8<>"",AH8*AE8,0) -> 43554 | AK8: Sudhist Enterprises | AL8: =AE8 -> 427 | AM8: 20 | AN8: =IF(AL8<>"",AM8*AL8,0) -> 8540 | AQ8: =IF(AO8<>"",AP8*AO8,0) -> 0 | AR8: =AQ8+AN8 -> 8540 | AT8: ETIL-PUR-ORD-23-10-00058 | AU8: 45211 | AV8: =AM8 -> 20 | AW8: =AV8*AL8 -> 8540 | AY8: SE/361 BG | AZ8: 45257 | BA8: =AM8 -> 20 | BB8: =AL8 -> 427 | BC8: =IF(BB8<>"",BB8*BA8,0) -> 8540
A9: =IF(B9<>"",A8+1,"") -> 7 | B9: 00001GF15-1GF150107 | C9: 1GF15 | D9: R-7 | E9: 1GF150107 | G9: Airtel | H9: Gorai | I9: Mumbai | J9: Mumbai | K9: Maharashtra | L9: 1GF | M9: 1GF | N9: 45141 | O9: 631 | P9: 45379 | Q9: 45379 | V9: 12F | W9: =O9 -> 631 | X9: =W9 -> 631 | Z9: BAL-ANG-UASL-Mumbai-Maharashtra/PUR/100 04346 | AA9: 14000 | AB9: 45181 | AC9: 102 | AE9: =X9 -> 631 | AF9: UA | AG9: 12F | AH9: 102 | AI9: =IF(AE9<>"",AH9*AE9,0) -> 64362 | AK9: Sudhist Enterprises | AL9: =AE9 -> 631 | AM9: 20 | AN9: =IF(AL9<>"",AM9*AL9,0) -> 12620 | AQ9: =IF(AO9<>"",AP9*AO9,0) -> 0 | AR9: =AQ9+AN9 -> 12620 | AT9: ETIL-PUR-ORD-23-10-00058 | AU9: 45211 | AV9: =AM9 -> 20 | AW9: =AV9*AL9 -> 12620 | AY9: SE/361 BG | AZ9: 45257 | BA9: =AM9 -> 20 | BB9: =AL9 -> 631 | BC9: =IF(BB9<>"",BB9*BA9,0) -> 12620
A10: =IF(B10<>"",A9+1,"") -> 8 | B10: 00001GF16-1GF160107 | C10: 1GF16 | D10: R-8 | E10: 1GF160107 | G10: Airtel | H10: Gorai | I10: Mumbai | J10: Mumbai | K10: Maharashtra | L10: 1GF | M10: 1GF | N10: 45145 | O10: 682 | P10: 45379 | Q10: 45379 | V10: 12F | W10: =O10 -> 682 | X10: =W10 -> 682 | Z10: BAL-ANG-UASL-Mumbai-Maharashtra/PUR/100 04346 | AA10: 14000 | AB10: 45181 | AC10: 102 | AE10: =X10 -> 682 | AF10: UA | AG10: 12F | AH10: 102 | AI10: =IF(AE10<>"",AH10*AE10,0) -> 69564 | AK10: Sudhist Enterprises | AL10: =AE10 -> 682 | AM10: 20 | AN10: =IF(AL10<>"",AM10*AL10,0) -> 13640 | AQ10: =IF(AO10<>"",AP10*AO10,0) -> 0 | AR10: =AQ10+AN10 -> 13640 | AT10: ETIL-PUR-ORD-23-10-00058 | AU10: 45211 | AV10: =AM10 -> 20 | AW10: =AV10*AL10 -> 13640 | AY10: SE/361 BG | AZ10: 45257 | BA10: =AM10 -> 20 | BB10: =AL10 -> 682 | BC10: =IF(BB10<>"",BB10*BA10,0) -> 13640
A11: =IF(B11<>"",A10+1,"") -> 9 | B11: 00001GF17-1GF170104 | C11: 1GF17 | D11: R-9 | E11: 1GF170104 | G11: Airtel | H11: Gorai | I11: Mumbai | J11: Mumbai | K11: Maharashtra | L11: 1GF | M11: 1GF | N11: 45145 | O11: 293 | P11: 45379 | Q11: 45379 | V11: 12F | W11: =O11 -> 293 | X11: =W11 -> 293 | Z11: BAL-ANG-UASL-Mumbai-Maharashtra/PUR/100 04346 | AA11: 14000 | AB11: 45181 | AC11: 102 | AE11: =X11 -> 293 | AF11: UA | AG11: 12F | AH11: 102 | AI11: =IF(AE11<>"",AH11*AE11,0) -> 29886 | AK11: Sudhist Enterprises | AL11: =AE11 -> 293 | AM11: 20 | AN11: =IF(AL11<>"",AM11*AL11,0) -> 5860 | AQ11: =IF(AO11<>"",AP11*AO11,0) -> 0 | AR11: =AQ11+AN11 -> 5860 | AT11: ETIL-PUR-ORD-23-10-00058 | AU11: 45211 | AV11: =AM11 -> 20 | AW11: =AV11*AL11 -> 5860 | AY11: SE/361 BG | AZ11: 45257 | BA11: =AM11 -> 20 | BB11: =AL11 -> 293 | BC11: =IF(BB11<>"",BB11*BA11,0) -> 5860
A12: =IF(B12<>"",A11+1,"") -> 10 | B12: 00001GF18-1GF180104 | C12: 1GF18 | D12: R-10 | E12: 1GF180104 | G12: Airtel | H12: Gorai | I12: Mumbai | J12: Mumbai | K12: Maharashtra | L12: 1GF | M12: 1GF | N12: 45145 | O12: 262 | P12: 45379 | Q12: 45379 | V12: 12F | W12: =O12 -> 262 | X12: =W12 -> 262 | Z12: BAL-ANG-UASL-Mumbai-Maharashtra/PUR/100 04346 | AA12: 14000 | AB12: 45181 | AC12: 102 | AE12: =X12 -> 262 | AF12: UA | AG12: 12F | AH12: 102 | AI12: =IF(AE12<>"",AH12*AE12,0) -> 26724 | AK12: Sudhist Enterprises | AL12: =AE12 -> 262 | AM12: 20 | AN12: =IF(AL12<>"",AM12*AL12,0) -> 5240 | AQ12: =IF(AO12<>"",AP12*AO12,0) -> 0 | AR12: =AQ12+AN12 -> 5240 | AT12: ETIL-PUR-ORD-23-10-00058 | AU12: 45211 | AV12: =AM12 -> 20 | AW12: =AV12*AL12 -> 5240 | AY12: SE/361 BG | AZ12: 45257 | BA12: =AM12 -> 20 | BB12: =AL12 -> 262 | BC12: =IF(BB12<>"",BB12*BA12,0) -> 5240
A13: =IF(B13<>"",A12+1,"") -> 11 | B13: 00001GF19-1GF190104 | C13: 1GF19 | D13: R-11 | E13: 1GF190104 | G13: Airtel | H13: Gorai | I13: Mumbai | J13: Mumbai | K13: Maharashtra | L13: 1GF | M13: 1GF | N13: 45145 | O13: 372 | P13: 45379 | Q13: 45379 | V13: 12F | W13: =O13 -> 372 | X13: =W13 -> 372 | Z13: BAL-ANG-UASL-Mumbai-Maharashtra/PUR/100 04346 | AA13: 14000 | AB13: 45181 | AC13: 102 | AE13: =X13 -> 372 | AF13: UA | AG13: 12F | AH13: 102 | AI13: =IF(AE13<>"",AH13*AE13,0) -> 37944 | AK13: Sudhist Enterprises | AL13: =AE13 -> 372 | AM13: 20 | AN13: =IF(AL13<>"",AM13*AL13,0) -> 7440 | AQ13: =IF(AO13<>"",AP13*AO13,0) -> 0 | AR13: =AQ13+AN13 -> 7440 | AT13: ETIL-PUR-ORD-23-10-00058 | AU13: 45211 | AV13: =AM13 -> 20 | AW13: =AV13*AL13 -> 7440 | AY13: SE/361 BG | AZ13: 45257 | BA13: =AM13 -> 20 | BB13: =AL13 -> 372 | BC13: =IF(BB13<>"",BB13*BA13,0) -> 7440
A14: =IF(B14<>"",A13+1,"") -> 12 | B14: 00001GF20-1GF200104 | C14: 1GF20 | D14: R-12 | E14: 1GF200104 | G14: Airtel | H14: Gorai | I14: Mumbai | J14: Mumbai | K14: Maharashtra | L14: 1GF | M14: 1GF | N14: 45145 | O14: 450 | P14: 45379 | Q14: 45379 | V14: 12F | W14: =O14 -> 450 | X14: =W14 -> 450 | Z14: BAL-ANG-UASL-Mumbai-Maharashtra/PUR/100 04346 | AA14: 14000 | AB14: 45181 | AC14: 102 | AE14: =X14 -> 450 | AF14: UA | AG14: 12F | AH14: 102 | AI14: =IF(AE14<>"",AH14*AE14,0) -> 45900 | AK14: Sudhist Enterprises | AL14: =AE14 -> 450 | AM14: 20 | AN14: =IF(AL14<>"",AM14*AL14,0) -> 9000 | AQ14: =IF(AO14<>"",AP14*AO14,0) -> 0 | AR14: =AQ14+AN14 -> 9000 | AT14: ETIL-PUR-ORD-23-10-00058 | AU14: 45211 | AV14: =AM14 -> 20 | AW14: =AV14*AL14 -> 9000 | AY14: SE/361 BG | AZ14: 45257 | BA14: =AM14 -> 20 | BB14: =AL14 -> 450 | BC14: =IF(BB14<>"",BB14*BA14,0) -> 9000
A15: =IF(B15<>"",A14+1,"") -> 13 | B15: 00001GF21-1GF210104 | C15: 1GF21 | D15: R-13 | E15: 1GF210104 | G15: Airtel | H15: Gorai | I15: Mumbai | J15: Mumbai | K15: Maharashtra | L15: 1GF | M15: 1GF | N15: 45145 | O15: 430 | P15: 45379 | Q15: 45379 | V15: 12F | W15: =O15 -> 430 | X15: =W15 -> 430 | Z15: BAL-ANG-UASL-Mumbai-Maharashtra/PUR/100 04346 | AA15: 14000 | AB15: 45181 | AC15: 102 | AE15: =X15 -> 430 | AF15: UA | AG15: 12F | AH15: 102 | AI15: =IF(AE15<>"",AH15*AE15,0) -> 43860 | AK15: Sudhist Enterprises | AL15: =AE15 -> 430 | AM15: 20 | AN15: =IF(AL15<>"",AM15*AL15,0) -> 8600 | AQ15: =IF(AO15<>"",AP15*AO15,0) -> 0 | AR15: =AQ15+AN15 -> 8600 | AT15: ETIL-PUR-ORD-23-10-00058 | AU15: 45211 | AV15: =AM15 -> 20 | AW15: =AV15*AL15 -> 8600 | AY15: SE/361 BG | AZ15: 45257 | BA15: =AM15 -> 20 | BB15: =AL15 -> 430 | BC15: =IF(BB15<>"",BB15*BA15,0) -> 8600
A16: =IF(B16<>"",A15+1,"") -> 14 | B16: 00001GF22-1GF210102 | C16: 1GF22 | D16: R-14 | E16: 1GF210102 | G16: Airtel | H16: Gorai | I16: Mumbai | J16: Mumbai | K16: Maharashtra | L16: 1GF | M16: 1GF | N16: 45145 | O16: 307 | P16: 45379 | Q16: 45379 | V16: 12F | W16: =O16 -> 307 | X16: =W16 -> 307 | Z16: BAL-ANG-UASL-Mumbai-Maharashtra/PUR/100 04346 | AA16: 14000 | AB16: 45181 | AC16: 102 | AE16: =X16 -> 307 | AF16: UA | AG16: 12F | AH16: 102 | AI16: =IF(AE16<>"",AH16*AE16,0) -> 31314 | AK16: Sudhist Enterprises | AL16: =AE16 -> 307 | AM16: 20 | AN16: =IF(AL16<>"",AM16*AL16,0) -> 6140 | AQ16: =IF(AO16<>"",AP16*AO16,0) -> 0 | AR16: =AQ16+AN16 -> 6140 | AT16: ETIL-PUR-ORD-23-10-00058 | AU16: 45211 | AV16: =AM16 -> 20 | AW16: =AV16*AL16 -> 6140 | AY16: SE/361 BG | AZ16: 45257 | BA16: =AM16 -> 20 | BB16: =AL16 -> 307 | BC16: =IF(BB16<>"",BB16*BA16,0) -> 6140
A17: =IF(B17<>"",A16+1,"") -> 15 | B17: 0000001GF-00001GF23 | C17: 1GF23 | D17: R-15 | E17: 1GF230102 | G17: Airtel | H17: Gorai | I17: Mumbai | J17: Mumbai | K17: Maharashtra | L17: 1GF | M17: 1GF | N17: 45092 | O17: 140 | P17: 45092 | Q17: 45092 | V17: 12F | W17: 140 | X17: 140 | Z17: BAL-ANG-UASL-Mumbai-Maharashtra/PUR/100 04346 | AA17: 14000 | AB17: 45181 | AC17: 102 | AE17: 140 | AF17: UA | AG17: 12F | AH17: 102 | AI17: =IF(AE17<>"",AH17*AE17,0) -> 14280 | AK17: Sudhist Enterprises | AL17: 140 | AM17: 20 | AN17: =IF(AL17<>"",AM17*AL17,0) -> 2800 | AQ17: =IF(AO17<>"",AP17*AO17,0) -> 0 | AR17: =AQ17+AN17 -> 2800 | AT17: ETIL-PUR-ORD-24-06-00029 | AU17: 45461 | AV17: =AM17 -> 20 | AW17: =AV17*AL17 -> 2800 | AY17: SE/458BG | AZ17: 45461 | BA17: =AM17 -> 20 | BB17: =AL17 -> 140 | BC17: =IF(BB17<>"",BB17*BA17,0) -> 2800
A18: =IF(B18<>"",A17+1,"") -> 16 | B18: 00001GF23-1GF240104 | C18: 1GF24 | D18: R-16 | E18: 1GF240104 | G18: Airtel | H18: Gorai | I18: Mumbai | J18: Mumbai | K18: Maharashtra | L18: 1GF | M18: 1GF | N18: 45092 | O18: 170 | P18: 45092 | Q18: 45092 | V18: 12F | W18: 170 | X18: 170 | Z18: BAL-ANG-UASL-Mumbai-Maharashtra/PUR/100 04346 | AA18: 14000 | AB18: 45181 | AC18: 102 | AE18: 170 | AF18: UA | AG18: 12F | AH18: 102 | AI18: =IF(AE18<>"",AH18*AE18,0) -> 17340 | AK18: Sudhist Enterprises | AL18: 170 | AM18: 20 | AN18: =IF(AL18<>"",AM18*AL18,0) -> 3400 | AQ18: =IF(AO18<>"",AP18*AO18,0) -> 0 | AR18: =AQ18+AN18 -> 3400 | AT18: ETIL-PUR-ORD-24-06-00029 | AU18: 45461 | AV18: =AM18 -> 20 | AW18: =AV18*AL18 -> 3400 | AY18: SE/458BG | AZ18: 45461 | BA18: =AM18 -> 20 | BB18: =AL18 -> 170 | BC18: =IF(BB18<>"",BB18*BA18,0) -> 3400

Sheet Node Details
E1: =MATCH(E2,'Route-Details'!$B$2:$X$2,0) -> 6 | F1: =MATCH(F2,'Route-Details'!$B$2:$X$2,0) -> 7 | G1: =MATCH(G2,'Route-Details'!$B$2:$X$2,0) -> 8 | H1: =MATCH(H2,'Route-Details'!$B$2:$X$2,0) -> 9 | I1: =MATCH(I2,'Route-Details'!$B$2:$X$2,0) -> 11 | J1: =MATCH(J2,'Route-Details'!$B$2:$X$2,0) -> 12 | S1: =SUBTOTAL(9,S3:S1048576) -> 7827
A2: Sr No | B2: FDC/FAT Unique ID (End Point) | C2: Latlong | D2: Route ID (Route on which FAT/FDC is connected) | E2: Customer | F2: Area Name | G2: City | H2: Telecom Circle | I2: OLT ID | J2: Cluster ID | K2: Online AT Date (Delivered) | L2: HOTO Date | M2: HOTO Signoff Date | N2: Start Date (Date from which we can bill) | O2: Lock-in Period | P2: Surrender Date | Q2: Any Additional Fiber used for connectivity | R2: Fiber Capacity | S2: Online AT Length (Delivered) | T2: OTDR length (in meters) | U2: Customer Billable length (in meters) | W2: Customer PO no | X2: PO length | Y2: PO Date | Z2: PO Rate | AB2: Fiber length deployed/used (in meters) | AC2: Fiber Type | AD2: Fiber Capacity | AE2: Fiber Rate per meter (incl Freight) | AF2: Fiber Material Cost | AH2: Execution Vendor Name | AI2: Vendor Billable Length (Fiber laying) | AJ2: Fiber Laying Rate | AK2: Fiber Laying/Execution Cost | AL2: OTM Length | AM2: OTM Execution Rate | AN2: OTM Cost | AO2: Total Vendor Cost | AQ2: Vendor PO No | AR2: Vendor PO Date | AS2: Vendor PO Rate | AT2: Vendor PO Cost | AV2: Vendor Invoice No | AW2: Vendor Invoice Date | AX2: Vendor Invoice Rate | AY2: Vendor Invoiced length | AZ2: Invoice Amt
A3: 1 | B3: 1GF12 | C3: R-1 | D3: 0000001GF-00001GF12 | E3: =_xlfn.IFNA(VLOOKUP($D3,'Route-Details'!$B$2:$X$1048576,'Node Details'!E$1,0),"") -> Airtel | F3: =_xlfn.IFNA(VLOOKUP($D3,'Route-Details'!$B$2:$X$1048576,'Node Details'!F$1,0),"") -> Gorai | G3: =_xlfn.IFNA(VLOOKUP($D3,'Route-Details'!$B$2:$X$1048576,'Node Details'!G$1,0),"") -> Mumbai | H3: =_xlfn.IFNA(VLOOKUP($D4,'Route-Details'!$B$2:$X$1048576,'Node Details'!H$1,0),"") -> Mumbai | I3: =_xlfn.IFNA(VLOOKUP($D3,'Route-Details'!$B$2:$X$1048576,'Node Details'!I$1,0),"") -> 1GF | J3: =_xlfn.IFNA(VLOOKUP($D3,'Route-Details'!$B$2:$X$1048576,'Node Details'!J$1,0),"") -> 1GF | K3: 45141 | L3: 45141 | M3: 45379 | R3: 24F | S3: 829 | T3: 829 | U3: 829 | W3: BAL-ANG-UASL-Mumbai-Maharashtra/PUR/100 04346 | X3: 3500 | Y3: 45181 | Z3: 122 | AB3: 829 | AC3: UA | AD3: 24F | AE3: 20 | AF3: =IF(AB3<>"",AE3*AB3,0) -> 16580 | AH3: Sudhist Enterprises | AI3: 829 | AJ3: 20 | AK3: =IF(AI3<>"",AJ3*AI3,0) -> 16580 | AN3: =IF(AL3<>"",AM3*AL3,0) -> 0 | AO3: =AN3+AK3 -> 16580 | AQ3: ETIL-PUR-ORD-23-10-00058 | AR3: 45211 | AS3: =AJ3 -> 20 | AT3: =AS3*AI3 -> 16580 | AV3: SE/361 BG | AW3: 45257 | AX3: =AJ3 -> 20 | AY3: =AI3 -> 829 | AZ3: =IF(AY3<>"",AY3*AX3,0) -> 16580
A4: =A3+1 -> 2 | B4: 1GF120101 | C4: R-4 | D4: 00001GF12-1GF120106 | E4: =_xlfn.IFNA(VLOOKUP($D4,'Route-Details'!$B$2:$X$1048576,'Node Details'!E$1,0),"") -> Airtel | F4: =_xlfn.IFNA(VLOOKUP($D4,'Route-Details'!$B$2:$X$1048576,'Node Details'!F$1,0),"") -> Gorai | G4: =_xlfn.IFNA(VLOOKUP($D4,'Route-Details'!$B$2:$X$1048576,'Node Details'!G$1,0),"") -> Mumbai | H4: =_xlfn.IFNA(VLOOKUP($D5,'Route-Details'!$B$2:$X$1048576,'Node Details'!H$1,0),"") -> Mumbai | I4: =_xlfn.IFNA(VLOOKUP($D4,'Route-Details'!$B$2:$X$1048576,'Node Details'!I$1,0),"") -> 1GF | J4: =_xlfn.IFNA(VLOOKUP($D4,'Route-Details'!$B$2:$X$1048576,'Node Details'!J$1,0),"") -> 1GF | K4: 45141 | L4: 45141 | M4: 45379 | R4: 24F | S4: 80 | T4: 80 | U4: 80 | W4: BAL-ANG-UASL-Mumbai-Maharashtra/PUR/100 04346 | X4: 3500 | Y4: 45181 | Z4: 122 | AB4: 80 | AC4: UA | AD4: 24F | AE4: 20 | AF4: =IF(AB4<>"",AE4*AB4,0) -> 1600 | AH4: Sudhist Enterprises | AI4: 80 | AJ4: 20 | AK4: =IF(AI4<>"",AJ4*AI4,0) -> 1600 | AN4: =IF(AL4<>"",AM4*AL4,0) -> 0 | AO4: =AN4+AK4 -> 1600 | AQ4: ETIL-PUR-ORD-23-10-00058 | AR4: 45211 | AS4: =AJ4 -> 20 | AT4: =AS4*AI4 -> 1600 | AV4: SE/361 BG | AW4: 45257 | AX4: =AJ4 -> 20 | AY4: =AI4 -> 80 | AZ4: =IF(AY4<>"",AY4*AX4,0) -> 1600
A5: =A4+1 -> 3 | B5: 1GF120102 | C5: R-4 | D5: 00001GF12-1GF120106 | E5: =_xlfn.IFNA(VLOOKUP($D5,'Route-Details'!$B$2:$X$1048576,'Node Details'!E$1,0),"") -> Airtel | F5: =_xlfn.IFNA(VLOOKUP($D5,'Route-Details'!$B$2:$X$1048576,'Node Details'!F$1,0),"") -> Gorai | G5: =_xlfn.IFNA(VLOOKUP($D5,'Route-Details'!$B$2:$X$1048576,'Node Details'!G$1,0),"") -> Mumbai | H5: =_xlfn.IFNA(VLOOKUP($D6,'Route-Details'!$B$2:$X$1048576,'Node Details'!H$1,0),"") -> Mumbai | I5: =_xlfn.IFNA(VLOOKUP($D5,'Route-Details'!$B$2:$X$1048576,'Node Details'!I$1,0),"") -> 1GF | J5: =_xlfn.IFNA(VLOOKUP($D5,'Route-Details'!$B$2:$X$1048576,'Node Details'!J$1,0),"") -> 1GF | K5: 45141 | L5: 45141 | M5: 45379 | R5: 24F | S5: 80 | T5: 80 | U5: 80 | W5: BAL-ANG-UASL-Mumbai-Maharashtra/PUR/100 04346 | X5: 3500 | Y5: 45181 | Z5: 122 | AB5: 80 | AC5: UA | AD5: 24F | AE5: 20 | AF5: =IF(AB5<>"",AE5*AB5,0) -> 1600 | AH5: Sudhist Enterprises | AI5: 80 | AJ5: 20 | AK5: =IF(AI5<>"",AJ5*AI5,0) -> 1600 | AN5: =IF(AL5<>"",AM5*AL5,0) -> 0 | AO5: =AN5+AK5 -> 1600 | AQ5: ETIL-PUR-ORD-23-10-00058 | AR5: 45211 | AS5: =AJ5 -> 20 | AT5: =AS5*AI5 -> 1600 | AV5: SE/361 BG | AW5: 45257 | AX5: =AJ5 -> 20 | AY5: =AI5 -> 80 | AZ5: =IF(AY5<>"",AY5*AX5,0) -> 1600
A6: =A5+1 -> 4 | B6: 1GF120103 | C6: R-4 | D6: 00001GF12-1GF120106 | E6: =_xlfn.IFNA(VLOOKUP($D6,'Route-Details'!$B$2:$X$1048576,'Node Details'!E$1,0),"") -> Airtel | F6: =_xlfn.IFNA(VLOOKUP($D6,'Route-Details'!$B$2:$X$1048576,'Node Details'!F$1,0),"") -> Gorai | G6: =_xlfn.IFNA(VLOOKUP($D6,'Route-Details'!$B$2:$X$1048576,'Node Details'!G$1,0),"") -> Mumbai | H6: =_xlfn.IFNA(VLOOKUP($D7,'Route-Details'!$B$2:$X$1048576,'Node Details'!H$1,0),"") -> Mumbai | I6: =_xlfn.IFNA(VLOOKUP($D6,'Route-Details'!$B$2:$X$1048576,'Node Details'!I$1,0),"") -> 1GF | J6: =_xlfn.IFNA(VLOOKUP($D6,'Route-Details'!$B$2:$X$1048576,'Node Details'!J$1,0),"") -> 1GF | K6: 45141 | L6: 45141 | M6: 45379 | R6: 24F | S6: 33 | T6: 33 | U6: 33 | W6: BAL-ANG-UASL-Mumbai-Maharashtra/PUR/100 04346 | X6: 3500 | Y6: 45181 | Z6: 122 | AB6: 33 | AC6: UA | AD6: 24F | AE6: 20 | AF6: =IF(AB6<>"",AE6*AB6,0) -> 660 | AH6: Sudhist Enterprises | AI6: 33 | AJ6: 20 | AK6: =IF(AI6<>"",AJ6*AI6,0) -> 660 | AN6: =IF(AL6<>"",AM6*AL6,0) -> 0 | AO6: =AN6+AK6 -> 660 | AQ6: ETIL-PUR-ORD-23-10-00058 | AR6: 45211 | AS6: =AJ6 -> 20 | AT6: =AS6*AI6 -> 660 | AV6: SE/361 BG | AW6: 45257 | AX6: =AJ6 -> 20 | AY6: =AI6 -> 33 | AZ6: =IF(AY6<>"",AY6*AX6,0) -> 660
A7: =A6+1 -> 5 | B7: 1GF120104 | C7: R-4 | D7: 00001GF12-1GF120106 | E7: =_xlfn.IFNA(VLOOKUP($D7,'Route-Details'!$B$2:$X$1048576,'Node Details'!E$1,0),"") -> Airtel | F7: =_xlfn.IFNA(VLOOKUP($D7,'Route-Details'!$B$2:$X$1048576,'Node Details'!F$1,0),"") -> Gorai | G7: =_xlfn.IFNA(VLOOKUP($D7,'Route-Details'!$B$2:$X$1048576,'Node Details'!G$1,0),"") -> Mumbai | H7: =_xlfn.IFNA(VLOOKUP($D8,'Route-Details'!$B$2:$X$1048576,'Node Details'!H$1,0),"") -> Mumbai | I7: =_xlfn.IFNA(VLOOKUP($D7,'Route-Details'!$B$2:$X$1048576,'Node Details'!I$1,0),"") -> 1GF | J7: =_xlfn.IFNA(VLOOKUP($D7,'Route-Details'!$B$2:$X$1048576,'Node Details'!J$1,0),"") -> 1GF | K7: 45141 | L7: 45141 | M7: 45379 | R7: 24F | S7: 36 | T7: 36 | U7: 36 | W7: BAL-ANG-UASL-Mumbai-Maharashtra/PUR/100 04346 | X7: 3500 | Y7: 45181 | Z7: 122 | AB7: 36 | AC7: UA | AD7: 24F | AE7: 20 | AF7: =IF(AB7<>"",AE7*AB7,0) -> 720 | AH7: Sudhist Enterprises | AI7: 36 | AJ7: 20 | AK7: =IF(AI7<>"",AJ7*AI7,0) -> 720 | AN7: =IF(AL7<>"",AM7*AL7,0) -> 0 | AO7: =AN7+AK7 -> 720 | AQ7: ETIL-PUR-ORD-23-10-00058 | AR7: 45211 | AS7: =AJ7 -> 20 | AT7: =AS7*AI7 -> 720 | AV7: SE/361 BG | AW7: 45257 | AX7: =AJ7 -> 20 | AY7: =AI7 -> 36 | AZ7: =IF(AY7<>"",AY7*AX7,0) -> 720
A8: =A7+1 -> 6 | B8: 1GF120105 | C8: R-4 | D8: 00001GF12-1GF120106 | E8: =_xlfn.IFNA(VLOOKUP($D8,'Route-Details'!$B$2:$X$1048576,'Node Details'!E$1,0),"") -> Airtel | F8: =_xlfn.IFNA(VLOOKUP($D8,'Route-Details'!$B$2:$X$1048576,'Node Details'!F$1,0),"") -> Gorai | G8: =_xlfn.IFNA(VLOOKUP($D8,'Route-Details'!$B$2:$X$1048576,'Node Details'!G$1,0),"") -> Mumbai | H8: =_xlfn.IFNA(VLOOKUP($D9,'Route-Details'!$B$2:$X$1048576,'Node Details'!H$1,0),"") -> Mumbai | I8: =_xlfn.IFNA(VLOOKUP($D8,'Route-Details'!$B$2:$X$1048576,'Node Details'!I$1,0),"") -> 1GF | J8: =_xlfn.IFNA(VLOOKUP($D8,'Route-Details'!$B$2:$X$1048576,'Node Details'!J$1,0),"") -> 1GF | K8: 45141 | L8: 45141 | M8: 45379 | R8: 24F | S8: 34 | T8: 34 | U8: 34 | W8: BAL-ANG-UASL-Mumbai-Maharashtra/PUR/100 04346 | X8: 3500 | Y8: 45181 | Z8: 122 | AB8: 34 | AC8: UA | AD8: 24F | AE8: 20 | AF8: =IF(AB8<>"",AE8*AB8,0) -> 680 | AH8: Sudhist Enterprises | AI8: 34 | AJ8: 20 | AK8: =IF(AI8<>"",AJ8*AI8,0) -> 680 | AN8: =IF(AL8<>"",AM8*AL8,0) -> 0 | AO8: =AN8+AK8 -> 680 | AQ8: ETIL-PUR-ORD-23-10-00058 | AR8: 45211 | AS8: =AJ8 -> 20 | AT8: =AS8*AI8 -> 680 | AV8: SE/361 BG | AW8: 45257 | AX8: =AJ8 -> 20 | AY8: =AI8 -> 34 | AZ8: =IF(AY8<>"",AY8*AX8,0) -> 680
A9: =A8+1 -> 7 | B9: 1GF120106 | C9: R-4 | D9: 00001GF12-1GF120106 | E9: =_xlfn.IFNA(VLOOKUP($D9,'Route-Details'!$B$2:$X$1048576,'Node Details'!E$1,0),"") -> Airtel | F9: =_xlfn.IFNA(VLOOKUP($D9,'Route-Details'!$B$2:$X$1048576,'Node Details'!F$1,0),"") -> Gorai | G9: =_xlfn.IFNA(VLOOKUP($D9,'Route-Details'!$B$2:$X$1048576,'Node Details'!G$1,0),"") -> Mumbai | H9: =_xlfn.IFNA(VLOOKUP($D10,'Route-Details'!$B$2:$X$1048576,'Node Details'!H$1,0),"") -> Mumbai | I9: =_xlfn.IFNA(VLOOKUP($D9,'Route-Details'!$B$2:$X$1048576,'Node Details'!I$1,0),"") -> 1GF | J9: =_xlfn.IFNA(VLOOKUP($D9,'Route-Details'!$B$2:$X$1048576,'Node Details'!J$1,0),"") -> 1GF | K9: 45141 | L9: 45141 | M9: 45379 | R9: 24F | S9: 34 | T9: 34 | U9: 34 | W9: BAL-ANG-UASL-Mumbai-Maharashtra/PUR/100 04346 | X9: 3500 | Y9: 45181 | Z9: 122 | AB9: 34 | AC9: UA | AD9: 24F | AE9: 20 | AF9: =IF(AB9<>"",AE9*AB9,0) -> 680 | AH9: Sudhist Enterprises | AI9: 34 | AJ9: 20 | AK9: =IF(AI9<>"",AJ9*AI9,0) -> 680 | AN9: =IF(AL9<>"",AM9*AL9,0) -> 0 | AO9: =AN9+AK9 -> 680 | AQ9: ETIL-PUR-ORD-23-10-00058 | AR9: 45211 | AS9: =AJ9 -> 20 | AT9: =AS9*AI9 -> 680 | AV9: SE/361 BG | AW9: 45257 | AX9: =AJ9 -> 20 | AY9: =AI9 -> 34 | AZ9: =IF(AY9<>"",AY9*AX9,0) -> 680
A10: =A9+1 -> 8 | B10: 1GF13 | C10: R-3 | D10: 00001GF12-00001GF22 | E10: =_xlfn.IFNA(VLOOKUP($D10,'Route-Details'!$B$2:$X$1048576,'Node Details'!E$1,0),"") -> Airtel | F10: =_xlfn.IFNA(VLOOKUP($D10,'Route-Details'!$B$2:$X$1048576,'Node Details'!F$1,0),"") -> Gorai | G10: =_xlfn.IFNA(VLOOKUP($D10,'Route-Details'!$B$2:$X$1048576,'Node Details'!G$1,0),"") -> Mumbai | H10: =_xlfn.IFNA(VLOOKUP($D11,'Route-Details'!$B$2:$X$1048576,'Node Details'!H$1,0),"") -> Mumbai | I10: =_xlfn.IFNA(VLOOKUP($D10,'Route-Details'!$B$2:$X$1048576,'Node Details'!I$1,0),"") -> 1GF | J10: =_xlfn.IFNA(VLOOKUP($D10,'Route-Details'!$B$2:$X$1048576,'Node Details'!J$1,0),"") -> 1GF | K10: 45145 | L10: 45145 | M10: 45379 | R10: 12F | S10: 162 | T10: 162 | U10: 162 | W10: BAL-ANG-UASL-Mumbai-Maharashtra/PUR/100 04346 | X10: 14000 | Y10: 45181 | Z10: 102 | AB10: 162 | AC10: UA | AD10: 12F | AE10: 20 | AF10: =IF(AB10<>"",AE10*AB10,0) -> 3240 | AH10: Sudhist Enterprises | AI10: 162 | AJ10: 20 | AK10: =IF(AI10<>"",AJ10*AI10,0) -> 3240 | AN10: =IF(AL10<>"",AM10*AL10,0) -> 0 | AO10: =AN10+AK10 -> 3240 | AQ10: ETIL-PUR-ORD-23-10-00058 | AR10: 45211 | AS10: =AJ10 -> 20 | AT10: =AS10*AI10 -> 3240 | AV10: SE/361 BG | AW10: 45257 | AX10: =AJ10 -> 20 | AY10: =AI10 -> 162 | AZ10: =IF(AY10<>"",AY10*AX10,0) -> 3240
A11: =A10+1 -> 9 | B11: 1GF130101 | C11: R-5 | D11: 00001GF13-1GF130106 | E11: =_xlfn.IFNA(VLOOKUP($D11,'Route-Details'!$B$2:$X$1048576,'Node Details'!E$1,0),"") -> Airtel | F11: =_xlfn.IFNA(VLOOKUP($D11,'Route-Details'!$B$2:$X$1048576,'Node Details'!F$1,0),"") -> Gorai | G11: =_xlfn.IFNA(VLOOKUP($D11,'Route-Details'!$B$2:$X$1048576,'Node Details'!G$1,0),"") -> Mumbai | H11: =_xlfn.IFNA(VLOOKUP($D12,'Route-Details'!$B$2:$X$1048576,'Node Details'!H$1,0),"") -> Mumbai | I11: =_xlfn.IFNA(VLOOKUP($D11,'Route-Details'!$B$2:$X$1048576,'Node Details'!I$1,0),"") -> 1GF | J11: =_xlfn.IFNA(VLOOKUP($D11,'Route-Details'!$B$2:$X$1048576,'Node Details'!J$1,0),"") -> 1GF | K11: 45145 | L11: 45145 | M11: 45379 | R11: 12F | S11: 107 | T11: 107 | U11: 107 | W11: BAL-ANG-UASL-Mumbai-Maharashtra/PUR/100 04346 | X11: 14000 | Y11: 45181 | Z11: 102 | AB11: 107 | AC11: UA | AD11: 12F | AE11: 20 | AF11: =IF(AB11<>"",AE11*AB11,0) -> 2140 | AH11: Sudhist Enterprises | AI11: 107 | AJ11: 20 | AK11: =IF(AI11<>"",AJ11*AI11,0) -> 2140 | AN11: =IF(AL11<>"",AM11*AL11,0) -> 0 | AO11: =AN11+AK11 -> 2140 | AQ11: ETIL-PUR-ORD-23-10-00058 | AR11: 45211 | AS11: =AJ11 -> 20 | AT11: =AS11*AI11 -> 2140 | AV11: SE/361 BG | AW11: 45257 | AX11: =AJ11 -> 20 | AY11: =AI11 -> 107 | AZ11: =IF(AY11<>"",AY11*AX11,0) -> 2140
A12: =A11+1 -> 10 | B12: 1GF130102 | C12: R-5 | D12: 00001GF13-1GF130106 | E12: =_xlfn.IFNA(VLOOKUP($D12,'Route-Details'!$B$2:$X$1048576,'Node Details'!E$1,0),"") -> Airtel | F12: =_xlfn.IFNA(VLOOKUP($D12,'Route-Details'!$B$2:$X$1048576,'Node Details'!F$1,0),"") -> Gorai | G12: =_xlfn.IFNA(VLOOKUP($D12,'Route-Details'!$B$2:$X$1048576,'Node Details'!G$1,0),"") -> Mumbai | H12: =_xlfn.IFNA(VLOOKUP($D13,'Route-Details'!$B$2:$X$1048576,'Node Details'!H$1,0),"") -> Mumbai | I12: =_xlfn.IFNA(VLOOKUP($D12,'Route-Details'!$B$2:$X$1048576,'Node Details'!I$1,0),"") -> 1GF | J12: =_xlfn.IFNA(VLOOKUP($D12,'Route-Details'!$B$2:$X$1048576,'Node Details'!J$1,0),"") -> 1GF | K12: 45145 | L12: 45145 | M12: 45379 | R12: 12F | S12: 54 | T12: 54 | U12: 54 | W12: BAL-ANG-UASL-Mumbai-Maharashtra/PUR/100 04346 | X12: 14000 | Y12: 45181 | Z12: 102 | AB12: 54 | AC12: UA | AD12: 12F | AE12: 20 | AF12: =IF(AB12<>"",AE12*AB12,0) -> 1080 | AH12: Sudhist Enterprises | AI12: 54 | AJ12: 20 | AK12: =IF(AI12<>"",AJ12*AI12,0) -> 1080 | AN12: =IF(AL12<>"",AM12*AL12,0) -> 0 | AO12: =AN12+AK12 -> 1080 | AQ12: ETIL-PUR-ORD-23-10-00058 | AR12: 45211 | AS12: =AJ12 -> 20 | AT12: =AS12*AI12 -> 1080 | AV12: SE/361 BG | AW12: 45257 | AX12: =AJ12 -> 20 | AY12: =AI12 -> 54 | AZ12: =IF(AY12<>"",AY12*AX12,0) -> 1080
A13: =A12+1 -> 11 | B13: 1GF130103 | C13: R-5 | D13: 00001GF13-1GF130106 | E13: =_xlfn.IFNA(VLOOKUP($D13,'Route-Details'!$B$2:$X$1048576,'Node Details'!E$1,0),"") -> Airtel | F13: =_xlfn.IFNA(VLOOKUP($D13,'Route-Details'!$B$2:$X$1048576,'Node Details'!F$1,0),"") -> Gorai | G13: =_xlfn.IFNA(VLOOKUP($D13,'Route-Details'!$B$2:$X$1048576,'Node Details'!G$1,0),"") -> Mumbai | H13: =_xlfn.IFNA(VLOOKUP($D14,'Route-Details'!$B$2:$X$1048576,'Node Details'!H$1,0),"") -> Mumbai | I13: =_xlfn.IFNA(VLOOKUP($D13,'Route-Details'!$B$2:$X$1048576,'Node Details'!I$1,0),"") -> 1GF | J13: =_xlfn.IFNA(VLOOKUP($D13,'Route-Details'!$B$2:$X$1048576,'Node Details'!J$1,0),"") -> 1GF | K13: 45145 | L13: 45145 | M13: 45379 | R13: 12F | S13: 54 | T13: 54 | U13: 54 | W13: BAL-ANG-UASL-Mumbai-Maharashtra/PUR/100 04346 | X13: 14000 | Y13: 45181 | Z13: 102 | AB13: 54 | AC13: UA | AD13: 12F | AE13: 20 | AF13: =IF(AB13<>"",AE13*AB13,0) -> 1080 | AH13: Sudhist Enterprises | AI13: 54 | AJ13: 20 | AK13: =IF(AI13<>"",AJ13*AI13,0) -> 1080 | AN13: =IF(AL13<>"",AM13*AL13,0) -> 0 | AO13: =AN13+AK13 -> 1080 | AQ13: ETIL-PUR-ORD-23-10-00058 | AR13: 45211 | AS13: =AJ13 -> 20 | AT13: =AS13*AI13 -> 1080 | AV13: SE/361 BG | AW13: 45257 | AX13: =AJ13 -> 20 | AY13: =AI13 -> 54 | AZ13: =IF(AY13<>"",AY13*AX13,0) -> 1080
A14: =A13+1 -> 12 | B14: 1GF130104 | C14: R-5 | D14: 00001GF13-1GF130106 | E14: =_xlfn.IFNA(VLOOKUP($D14,'Route-Details'!$B$2:$X$1048576,'Node Details'!E$1,0),"") -> Airtel | F14: =_xlfn.IFNA(VLOOKUP($D14,'Route-Details'!$B$2:$X$1048576,'Node Details'!F$1,0),"") -> Gorai | G14: =_xlfn.IFNA(VLOOKUP($D14,'Route-Details'!$B$2:$X$1048576,'Node Details'!G$1,0),"") -> Mumbai | H14: =_xlfn.IFNA(VLOOKUP($D15,'Route-Details'!$B$2:$X$1048576,'Node Details'!H$1,0),"") -> Mumbai | I14: =_xlfn.IFNA(VLOOKUP($D14,'Route-Details'!$B$2:$X$1048576,'Node Details'!I$1,0),"") -> 1GF | J14: =_xlfn.IFNA(VLOOKUP($D14,'Route-Details'!$B$2:$X$1048576,'Node Details'!J$1,0),"") -> 1GF | K14: 45145 | L14: 45145 | M14: 45379 | R14: 12F | S14: 52 | T14: 52 | U14: 52 | W14: BAL-ANG-UASL-Mumbai-Maharashtra/PUR/100 04346 | X14: 14000 | Y14: 45181 | Z14: 102 | AB14: 52 | AC14: UA | AD14: 12F | AE14: 20 | AF14: =IF(AB14<>"",AE14*AB14,0) -> 1040 | AH14: Sudhist Enterprises | AI14: 52 | AJ14: 20 | AK14: =IF(AI14<>"",AJ14*AI14,0) -> 1040 | AN14: =IF(AL14<>"",AM14*AL14,0) -> 0 | AO14: =AN14+AK14 -> 1040 | AQ14: ETIL-PUR-ORD-23-10-00058 | AR14: 45211 | AS14: =AJ14 -> 20 | AT14: =AS14*AI14 -> 1040 | AV14: SE/361 BG | AW14: 45257 | AX14: =AJ14 -> 20 | AY14: =AI14 -> 52 | AZ14: =IF(AY14<>"",AY14*AX14,0) -> 1040
A15: =A14+1 -> 13 | B15: 1GF130105 | C15: R-5 | D15: 00001GF13-1GF130106 | E15: =_xlfn.IFNA(VLOOKUP($D15,'Route-Details'!$B$2:$X$1048576,'Node Details'!E$1,0),"") -> Airtel | F15: =_xlfn.IFNA(VLOOKUP($D15,'Route-Details'!$B$2:$X$1048576,'Node Details'!F$1,0),"") -> Gorai | G15: =_xlfn.IFNA(VLOOKUP($D15,'Route-Details'!$B$2:$X$1048576,'Node Details'!G$1,0),"") -> Mumbai | H15: =_xlfn.IFNA(VLOOKUP($D16,'Route-Details'!$B$2:$X$1048576,'Node Details'!H$1,0),"") -> Mumbai | I15: =_xlfn.IFNA(VLOOKUP($D15,'Route-Details'!$B$2:$X$1048576,'Node Details'!I$1,0),"") -> 1GF | J15: =_xlfn.IFNA(VLOOKUP($D15,'Route-Details'!$B$2:$X$1048576,'Node Details'!J$1,0),"") -> 1GF | K15: 45145 | L15: 45145 | M15: 45379 | R15: 12F | S15: 50 | T15: 50 | U15: 50 | W15: BAL-ANG-UASL-Mumbai-Maharashtra/PUR/100 04346 | X15: 14000 | Y15: 45181 | Z15: 102 | AB15: 50 | AC15: UA | AD15: 12F | AE15: 20 | AF15: =IF(AB15<>"",AE15*AB15,0) -> 1000 | AH15: Sudhist Enterprises | AI15: 50 | AJ15: 20 | AK15: =IF(AI15<>"",AJ15*AI15,0) -> 1000 | AN15: =IF(AL15<>"",AM15*AL15,0) -> 0 | AO15: =AN15+AK15 -> 1000 | AQ15: ETIL-PUR-ORD-23-10-00058 | AR15: 45211 | AS15: =AJ15 -> 20 | AT15: =AS15*AI15 -> 1000 | AV15: SE/361 BG | AW15: 45257 | AX15: =AJ15 -> 20 | AY15: =AI15 -> 50 | AZ15: =IF(AY15<>"",AY15*AX15,0) -> 1000
... A66: =A65+1 -> 64 | B66: 1GF22 | C66: R-3 | D66: 00001GF12-00001GF22 | E66: =_xlfn.IFNA(VLOOKUP($D66,'Route-Details'!$B$2:$X$1048576,'Node Details'!E$1,0),"") -> Airtel | F66: =_xlfn.IFNA(VLOOKUP($D66,'Route-Details'!$B$2:$X$1048576,'Node Details'!F$1,0),"") -> Gorai | G66: =_xlfn.IFNA(VLOOKUP($D66,'Route-Details'!$B$2:$X$1048576,'Node Details'!G$1,0),"") -> Mumbai | H66: =_xlfn.IFNA(VLOOKUP($D67,'Route-Details'!$B$2:$X$1048576,'Node Details'!H$1,0),"") -> Mumbai | I66: =_xlfn.IFNA(VLOOKUP($D66,'Route-Details'!$B$2:$X$1048576,'Node Details'!I$1,0),"") -> 1GF | J66: =_xlfn.IFNA(VLOOKUP($D66,'Route-Details'!$B$2:$X$1048576,'Node Details'!J$1,0),"") -> 1GF | K66: 45229 | L66: 45229 | M66: 45379 | R66: 12F | S66: 75 | T66: 75 | U66: 75 | W66: BAL-ANG-UASL-Mumbai-Maharashtra/PUR/100 04346 | X66: 14000 | Y66: 45181 | Z66: 102 | AB66: 75 | AC66: UA | AD66: 12F | AE66: 20 | AF66: =IF(AB66<>"",AE66*AB66,0) -> 1500 | AH66: Sudhist Enterprises | AI66: 75 | AJ66: 20 | AK66: =IF(AI66<>"",AJ66*AI66,0) -> 1500 | AN66: =IF(AL66<>"",AM66*AL66,0) -> 0 | AO66: =AN66+AK66 -> 1500 | AQ66: ETIL-PUR-ORD-23-10-00058 | AR66: 45211 | AS66: =AJ66 -> 20 | AT66: =AS66*AI66 -> 1500 | AV66: SE/361 BG | AW66: 45257 | AX66: =AJ66 -> 20 | AY66: =AI66 -> 75 | AZ66: =IF(AY66<>"",AY66*AX66,0) -> 1500
A67: =A66+1 -> 65 | B67: 1GF220101 | C67: R-14 | D67: 00001GF22-1GF210102 | E67: =_xlfn.IFNA(VLOOKUP($D67,'Route-Details'!$B$2:$X$1048576,'Node Details'!E$1,0),"") -> Airtel | F67: =_xlfn.IFNA(VLOOKUP($D67,'Route-Details'!$B$2:$X$1048576,'Node Details'!F$1,0),"") -> Gorai | G67: =_xlfn.IFNA(VLOOKUP($D67,'Route-Details'!$B$2:$X$1048576,'Node Details'!G$1,0),"") -> Mumbai | H67: =_xlfn.IFNA(VLOOKUP($D68,'Route-Details'!$B$2:$X$1048576,'Node Details'!H$1,0),"") -> Mumbai | I67: =_xlfn.IFNA(VLOOKUP($D67,'Route-Details'!$B$2:$X$1048576,'Node Details'!I$1,0),"") -> 1GF | J67: =_xlfn.IFNA(VLOOKUP($D67,'Route-Details'!$B$2:$X$1048576,'Node Details'!J$1,0),"") -> 1GF | K67: 45229 | L67: 45229 | M67: WIP | R67: 12F | S67: 94 | T67: 94 | U67: 94 | W67: BAL-ANG-UASL-Mumbai-Maharashtra/PUR/100 04346 | X67: 14000 | Y67: 45181 | Z67: 102 | AB67: 94 | AC67: UA | AD67: 12F | AE67: 20 | AF67: =IF(AB67<>"",AE67*AB67,0) -> 1880 | AH67: Sudhist Enterprises | AI67: 94 | AJ67: 20 | AK67: =IF(AI67<>"",AJ67*AI67,0) -> 1880 | AN67: =IF(AL67<>"",AM67*AL67,0) -> 0 | AO67: =AN67+AK67 -> 1880 | AQ67: ETIL-PUR-ORD-23-10-00058 | AR67: 45211 | AS67: =AJ67 -> 20 | AT67: =AS67*AI67 -> 1880 | AV67: SE/361 BG | AW67: 45257 | AX67: =AJ67 -> 20 | AY67: =AI67 -> 94 | AZ67: =IF(AY67<>"",AY67*AX67,0) -> 1880
A68: =A67+1 -> 66 | B68: 1GF220102 | C68: R-14 | D68: 00001GF22-1GF210102 | E68: =_xlfn.IFNA(VLOOKUP($D68,'Route-Details'!$B$2:$X$1048576,'Node Details'!E$1,0),"") -> Airtel | F68: =_xlfn.IFNA(VLOOKUP($D68,'Route-Details'!$B$2:$X$1048576,'Node Details'!F$1,0),"") -> Gorai | G68: =_xlfn.IFNA(VLOOKUP($D68,'Route-Details'!$B$2:$X$1048576,'Node Details'!G$1,0),"") -> Mumbai | H68: =_xlfn.IFNA(VLOOKUP($D69,'Route-Details'!$B$2:$X$1048576,'Node Details'!H$1,0),"") -> Mumbai | I68: =_xlfn.IFNA(VLOOKUP($D68,'Route-Details'!$B$2:$X$1048576,'Node Details'!I$1,0),"") -> 1GF | J68: =_xlfn.IFNA(VLOOKUP($D68,'Route-Details'!$B$2:$X$1048576,'Node Details'!J$1,0),"") -> 1GF | K68: 45229 | L68: 45229 | M68: WIP | R68: 12F | S68: 213 | T68: 213 | U68: 213 | W68: BAL-ANG-UASL-Mumbai-Maharashtra/PUR/100 04346 | X68: 14000 | Y68: 45181 | Z68: 102 | AB68: 213 | AC68: UA | AD68: 12F | AE68: 20 | AF68: =IF(AB68<>"",AE68*AB68,0) -> 4260 | AH68: Sudhist Enterprises | AI68: 213 | AJ68: 20 | AK68: =IF(AI68<>"",AJ68*AI68,0) -> 4260 | AN68: =IF(AL68<>"",AM68*AL68,0) -> 0 | AO68: =AN68+AK68 -> 4260 | AQ68: ETIL-PUR-ORD-23-10-00058 | AR68: 45211 | AS68: =AJ68 -> 20 | AT68: =AS68*AI68 -> 4260 | AV68: SE/361 BG | AW68: 45257 | AX68: =AJ68 -> 20 | AY68: =AI68 -> 213 | AZ68: =IF(AY68<>"",AY68*AX68,0) -> 4260
A69: =A68+1 -> 67 | B69: 1GF | C69: R-2 | D69: 00001GF22-0000001GF | E69: =_xlfn.IFNA(VLOOKUP($D69,'Route-Details'!$B$2:$X$1048576,'Node Details'!E$1,0),"") -> Airtel | F69: =_xlfn.IFNA(VLOOKUP($D69,'Route-Details'!$B$2:$X$1048576,'Node Details'!F$1,0),"") -> Gorai | G69: =_xlfn.IFNA(VLOOKUP($D69,'Route-Details'!$B$2:$X$1048576,'Node Details'!G$1,0),"") -> Mumbai | H69: =_xlfn.IFNA(VLOOKUP($D70,'Route-Details'!$B$2:$X$1048576,'Node Details'!H$1,0),"") -> Mumbai | I69: =_xlfn.IFNA(VLOOKUP($D69,'Route-Details'!$B$2:$X$1048576,'Node Details'!I$1,0),"") -> 1GF | J69: =_xlfn.IFNA(VLOOKUP($D69,'Route-Details'!$B$2:$X$1048576,'Node Details'!J$1,0),"") -> 1GF | K69: 45229 | L69: 45229 | M69: 45379 | R69: 24F | S69: 800 | T69: 800 | U69: 800 | W69: BAL-ANG-UASL-Mumbai-Maharashtra/PUR/100 04346 | X69: 3500 | Y69: 45181 | Z69: 122 | AB69: 800 | AC69: UA | AD69: 24F | AE69: 20 | AF69: =IF(AB69<>"",AE69*AB69,0) -> 16000 | AH69: Sudhist Enterprises | AI69: 800 | AJ69: 20 | AK69: =IF(AI69<>"",AJ69*AI69,0) -> 16000 | AN69: =IF(AL69<>"",AM69*AL69,0) -> 0 | AO69: =AN69+AK69 -> 16000 | AQ69: ETIL-PUR-ORD-23-10-00058 | AR69: 45211 | AS69: =AJ69 -> 20 | AT69: =AS69*AI69 -> 16000 | AV69: SE/361 BG | AW69: 45257 | AX69: =AJ69 -> 20 | AY69: =AI69 -> 800 | AZ69: =IF(AY69<>"",AY69*AX69,0) -> 16000
A70: =A69+1 -> 68 | B70: 1GF220103 | C70: R-14 | D70: 00001GF22-1GF210102 | E70: =_xlfn.IFNA(VLOOKUP($D70,'Route-Details'!$B$2:$X$1048576,'Node Details'!E$1,0),"") -> Airtel | F70: =_xlfn.IFNA(VLOOKUP($D70,'Route-Details'!$B$2:$X$1048576,'Node Details'!F$1,0),"") -> Gorai | G70: =_xlfn.IFNA(VLOOKUP($D70,'Route-Details'!$B$2:$X$1048576,'Node Details'!G$1,0),"") -> Mumbai | H70: =_xlfn.IFNA(VLOOKUP($D71,'Route-Details'!$B$2:$X$1048576,'Node Details'!H$1,0),"") -> Mumbai | I70: =_xlfn.IFNA(VLOOKUP($D70,'Route-Details'!$B$2:$X$1048576,'Node Details'!I$1,0),"") -> 1GF | J70: =_xlfn.IFNA(VLOOKUP($D70,'Route-Details'!$B$2:$X$1048576,'Node Details'!J$1,0),"") -> 1GF | K70: 45229 | L70: 45229 | M70: WIP | AF70: =IF(AB70<>"",AE70*AB70,0) -> 0 | AJ70: 20 | AK70: =IF(AI70<>"",AJ70*AI70,0) -> 0 | AN70: =IF(AL70<>"",AM70*AL70,0) -> 0 | AO70: =AN70+AK70 -> 0 | AS70: =AJ70 -> 20 | AT70: =AS70*AI70 -> 0 | AX70: =AJ70 -> 20 | AY70: =AI70 -> 0 | AZ70: =IF(AY70<>"",AY70*AX70,0) -> 0
A71: =A70+1 -> 69 | B71: 1GF220104 | C71: R-14 | D71: 00001GF22-1GF210102 | E71: =_xlfn.IFNA(VLOOKUP($D71,'Route-Details'!$B$2:$X$1048576,'Node Details'!E$1,0),"") -> Airtel | F71: =_xlfn.IFNA(VLOOKUP($D71,'Route-Details'!$B$2:$X$1048576,'Node Details'!F$1,0),"") -> Gorai | G71: =_xlfn.IFNA(VLOOKUP($D71,'Route-Details'!$B$2:$X$1048576,'Node Details'!G$1,0),"") -> Mumbai | H71: =_xlfn.IFNA(VLOOKUP($D72,'Route-Details'!$B$2:$X$1048576,'Node Details'!H$1,0),"") -> Mumbai | I71: =_xlfn.IFNA(VLOOKUP($D71,'Route-Details'!$B$2:$X$1048576,'Node Details'!I$1,0),"") -> 1GF | J71: =_xlfn.IFNA(VLOOKUP($D71,'Route-Details'!$B$2:$X$1048576,'Node Details'!J$1,0),"") -> 1GF | K71: 45229 | L71: 45229 | M71: WIP | AF71: =IF(AB71<>"",AE71*AB71,0) -> 0 | AJ71: 20 | AK71: =IF(AI71<>"",AJ71*AI71,0) -> 0 | AN71: =IF(AL71<>"",AM71*AL71,0) -> 0 | AO71: =AN71+AK71 -> 0 | AS71: =AJ71 -> 20 | AT71: =AS71*AI71 -> 0 | AX71: =AJ71 -> 20 | AY71: =AI71 -> 0 | AZ71: =IF(AY71<>"",AY71*AX71,0) -> 0
A72: =A71+1 -> 70 | B72: 1GF220105 | C72: R-14 | D72: 00001GF22-1GF210102 | E72: =_xlfn.IFNA(VLOOKUP($D72,'Route-Details'!$B$2:$X$1048576,'Node Details'!E$1,0),"") -> Airtel | F72: =_xlfn.IFNA(VLOOKUP($D72,'Route-Details'!$B$2:$X$1048576,'Node Details'!F$1,0),"") -> Gorai | G72: =_xlfn.IFNA(VLOOKUP($D72,'Route-Details'!$B$2:$X$1048576,'Node Details'!G$1,0),"") -> Mumbai | H72: =_xlfn.IFNA(VLOOKUP($D73,'Route-Details'!$B$2:$X$1048576,'Node Details'!H$1,0),"") -> Mumbai | I72: =_xlfn.IFNA(VLOOKUP($D72,'Route-Details'!$B$2:$X$1048576,'Node Details'!I$1,0),"") -> 1GF | J72: =_xlfn.IFNA(VLOOKUP($D72,'Route-Details'!$B$2:$X$1048576,'Node Details'!J$1,0),"") -> 1GF | K72: 45229 | L72: 45229 | M72: WIP | AF72: =IF(AB72<>"",AE72*AB72,0) -> 0 | AJ72: 20 | AK72: =IF(AI72<>"",AJ72*AI72,0) -> 0 | AN72: =IF(AL72<>"",AM72*AL72,0) -> 0 | AO72: =AN72+AK72 -> 0 | AS72: =AJ72 -> 20 | AT72: =AS72*AI72 -> 0 | AX72: =AJ72 -> 20 | AY72: =AI72 -> 0 | AZ72: =IF(AY72<>"",AY72*AX72,0) -> 0
A73: =A72+1 -> 71 | B73: 1GF220106 | C73: R-14 | D73: 00001GF22-1GF210102 | E73: =_xlfn.IFNA(VLOOKUP($D73,'Route-Details'!$B$2:$X$1048576,'Node Details'!E$1,0),"") -> Airtel | F73: =_xlfn.IFNA(VLOOKUP($D73,'Route-Details'!$B$2:$X$1048576,'Node Details'!F$1,0),"") -> Gorai | G73: =_xlfn.IFNA(VLOOKUP($D73,'Route-Details'!$B$2:$X$1048576,'Node Details'!G$1,0),"") -> Mumbai | H73: =_xlfn.IFNA(VLOOKUP($D74,'Route-Details'!$B$2:$X$1048576,'Node Details'!H$1,0),"") -> Mumbai | I73: =_xlfn.IFNA(VLOOKUP($D73,'Route-Details'!$B$2:$X$1048576,'Node Details'!I$1,0),"") -> 1GF | J73: =_xlfn.IFNA(VLOOKUP($D73,'Route-Details'!$B$2:$X$1048576,'Node Details'!J$1,0),"") -> 1GF | K73: 45229 | L73: 45229 | M73: WIP | AF73: =IF(AB73<>"",AE73*AB73,0) -> 0 | AJ73: 20 | AK73: =IF(AI73<>"",AJ73*AI73,0) -> 0 | AN73: =IF(AL73<>"",AM73*AL73,0) -> 0 | AO73: =AN73+AK73 -> 0 | AS73: =AJ73 -> 20 | AT73: =AS73*AI73 -> 0 | AX73: =AJ73 -> 20 | AY73: =AI73 -> 0 | AZ73: =IF(AY73<>"",AY73*AX73,0) -> 0
A74: =A73+1 -> 72 | B74: 1GF120107 | C74: R-4 | D74: 00001GF12-1GF120106 | E74: =_xlfn.IFNA(VLOOKUP($D74,'Route-Details'!$B$2:$X$1048576,'Node Details'!E$1,0),"") -> Airtel | F74: =_xlfn.IFNA(VLOOKUP($D74,'Route-Details'!$B$2:$X$1048576,'Node Details'!F$1,0),"") -> Gorai | G74: =_xlfn.IFNA(VLOOKUP($D74,'Route-Details'!$B$2:$X$1048576,'Node Details'!G$1,0),"") -> Mumbai | H74: =_xlfn.IFNA(VLOOKUP($D75,'Route-Details'!$B$2:$X$1048576,'Node Details'!H$1,0),"") -> Mumbai | I74: =_xlfn.IFNA(VLOOKUP($D74,'Route-Details'!$B$2:$X$1048576,'Node Details'!I$1,0),"") -> 1GF | J74: =_xlfn.IFNA(VLOOKUP($D74,'Route-Details'!$B$2:$X$1048576,'Node Details'!J$1,0),"") -> 1GF | K74: 45092 | L74: 45092 | M74: WIP | R74: 12F | S74: 51 | T74: 51 | U74: 51 | W74: BAL-ANG-UASL-Mumbai-Maharashtra/PUR/100 04346 | X74: 14000 | Y74: 45181 | Z74: 102 | AB74: 51 | AC74: UA | AD74: 12F | AE74: 20 | AF74: =IF(AB74<>"",AE74*AB74,0) -> 1020 | AH74: Sudhist Enterprises | AI74: 51 | AJ74: 20 | AK74: =IF(AI74<>"",AJ74*AI74,0) -> 1020 | AN74: =IF(AL74<>"",AM74*AL74,0) -> 0 | AO74: =AN74+AK74 -> 1020 | AQ74: ETIL-PUR-ORD-24-06-00029 | AR74: 45461 | AS74: =AJ74 -> 20 | AT74: =AS74*AI74 -> 1020 | AV74: SE/458BG | AW74: 45461 | AX74: =AJ74 -> 20 | AY74: =AI74 -> 51 | AZ74: =IF(AY74<>"",AY74*AX74,0) -> 1020
A75: =A74+1 -> 73 | B75: 1GF120108 | C75: R-4 | D75: 00001GF12-1GF120106 | E75: =_xlfn.IFNA(VLOOKUP($D75,'Route-Details'!$B$2:$X$1048576,'Node Details'!E$1,0),"") -> Airtel | F75: =_xlfn.IFNA(VLOOKUP($D75,'Route-Details'!$B$2:$X$1048576,'Node Details'!F$1,0),"") -> Gorai | G75: =_xlfn.IFNA(VLOOKUP($D75,'Route-Details'!$B$2:$X$1048576,'Node Details'!G$1,0),"") -> Mumbai | H75: =_xlfn.IFNA(VLOOKUP($D76,'Route-Details'!$B$2:$X$1048576,'Node Details'!H$1,0),"") -> Mumbai | I75: =_xlfn.IFNA(VLOOKUP($D75,'Route-Details'!$B$2:$X$1048576,'Node Details'!I$1,0),"") -> 1GF | J75: =_xlfn.IFNA(VLOOKUP($D75,'Route-Details'!$B$2:$X$1048576,'Node Details'!J$1,0),"") -> 1GF | K75: 45092 | L75: 45092 | M75: WIP | W75: BAL-ANG-UASL-Mumbai-Maharashtra/PUR/100 04346 | X75: 14000 | Y75: 45181 | Z75: 102 | AF75: =IF(AB75<>"",AE75*AB75,0) -> 0 | AH75: Sudhist Enterprises | AJ75: 20 | AK75: =IF(AI75<>"",AJ75*AI75,0) -> 0 | AN75: =IF(AL75<>"",AM75*AL75,0) -> 0 | AO75: =AN75+AK75 -> 0 | AQ75: ETIL-PUR-ORD-24-06-00029 | AR75: 45461 | AS75: =AJ75 -> 20 | AT75: =AS75*AI75 -> 0 | AV75: SE/458BG | AW75: 45461 | AX75: =AJ75 -> 20 | AY75: =AI75 -> 0 | AZ75: =IF(AY75<>"",AY75*AX75,0) -> 0
A76: =A75+1 -> 74 | B76: 1GF23 | C76: R-15 | D76: 00001GF12-1GF120106 | E76: =_xlfn.IFNA(VLOOKUP($D76,'Route-Details'!$B$2:$X$1048576,'Node Details'!E$1,0),"") -> Airtel | F76: =_xlfn.IFNA(VLOOKUP($D76,'Route-Details'!$B$2:$X$1048576,'Node Details'!F$1,0),"") -> Gorai | G76: =_xlfn.IFNA(VLOOKUP($D76,'Route-Details'!$B$2:$X$1048576,'Node Details'!G$1,0),"") -> Mumbai | H76: =_xlfn.IFNA(VLOOKUP($D77,'Route-Details'!$B$2:$X$1048576,'Node Details'!H$1,0),"") -> Mumbai | I76: =_xlfn.IFNA(VLOOKUP($D76,'Route-Details'!$B$2:$X$1048576,'Node Details'!I$1,0),"") -> 1GF | J76: =_xlfn.IFNA(VLOOKUP($D76,'Route-Details'!$B$2:$X$1048576,'Node Details'!J$1,0),"") -> 1GF | K76: 45092 | L76: 45092 | M76: WIP | R76: 12F | S76: 140 | T76: 140 | U76: 140 | W76: BAL-ANG-UASL-Mumbai-Maharashtra/PUR/100 04346 | X76: 14000 | Y76: 45181 | Z76: 102 | AB76: 140 | AC76: UA | AD76: 12F | AE76: 20 | AF76: =IF(AB76<>"",AE76*AB76,0) -> 2800 | AH76: Sudhist Enterprises | AI76: 140 | AJ76: 20 | AK76: =IF(AI76<>"",AJ76*AI76,0) -> 2800 | AN76: =IF(AL76<>"",AM76*AL76,0) -> 0 | AO76: =AN76+AK76 -> 2800 | AQ76: ETIL-PUR-ORD-24-06-00029 | AR76: 45461 | AS76: =AJ76 -> 20 | AT76: =AS76*AI76 -> 2800 | AV76: SE/458BG | AW76: 45461 | AX76: =AJ76 -> 20 | AY76: =AI76 -> 140 | AZ76: =IF(AY76<>"",AY76*AX76,0) -> 2800
A77: =A76+1 -> 75 | B77: 1GF230101 | C77: R-15 | D77: 00001GF12-1GF120106 | E77: =_xlfn.IFNA(VLOOKUP($D77,'Route-Details'!$B$2:$X$1048576,'Node Details'!E$1,0),"") -> Airtel | F77: =_xlfn.IFNA(VLOOKUP($D77,'Route-Details'!$B$2:$X$1048576,'Node Details'!F$1,0),"") -> Gorai | G77: =_xlfn.IFNA(VLOOKUP($D77,'Route-Details'!$B$2:$X$1048576,'Node Details'!G$1,0),"") -> Mumbai | H77: =_xlfn.IFNA(VLOOKUP($D78,'Route-Details'!$B$2:$X$1048576,'Node Details'!H$1,0),"") -> Mumbai | I77: =_xlfn.IFNA(VLOOKUP($D77,'Route-Details'!$B$2:$X$1048576,'Node Details'!I$1,0),"") -> 1GF | J77: =_xlfn.IFNA(VLOOKUP($D77,'Route-Details'!$B$2:$X$1048576,'Node Details'!J$1,0),"") -> 1GF | K77: 45092 | L77: 45092 | M77: WIP | W77: BAL-ANG-UASL-Mumbai-Maharashtra/PUR/100 04346 | X77: 14000 | Y77: 45181 | Z77: 102 | AF77: =IF(AB77<>"",AE77*AB77,0) -> 0 | AH77: Sudhist Enterprises | AJ77: 20 | AK77: =IF(AI77<>"",AJ77*AI77,0) -> 0 | AN77: =IF(AL77<>"",AM77*AL77,0) -> 0 | AO77: =AN77+AK77 -> 0 | AQ77: ETIL-PUR-ORD-24-06-00029 | AR77: 45461 | AS77: =AJ77 -> 20 | AT77: =AS77*AI77 -> 0 | AV77: SE/458BG | AW77: 45461 | AX77: =AJ77 -> 20 | AY77: =AI77 -> 0 | AZ77: =IF(AY77<>"",AY77*AX77,0) -> 0
A78: =A77+1 -> 76 | B78: 1GF230102 | C78: R-15 | D78: 00001GF12-1GF120106 | E78: =_xlfn.IFNA(VLOOKUP($D78,'Route-Details'!$B$2:$X$1048576,'Node Details'!E$1,0),"") -> Airtel | F78: =_xlfn.IFNA(VLOOKUP($D78,'Route-Details'!$B$2:$X$1048576,'Node Details'!F$1,0),"") -> Gorai | G78: =_xlfn.IFNA(VLOOKUP($D78,'Route-Details'!$B$2:$X$1048576,'Node Details'!G$1,0),"") -> Mumbai | H78: =_xlfn.IFNA(VLOOKUP($D79,'Route-Details'!$B$2:$X$1048576,'Node Details'!H$1,0),"") -> Mumbai | I78: =_xlfn.IFNA(VLOOKUP($D78,'Route-Details'!$B$2:$X$1048576,'Node Details'!I$1,0),"") -> 1GF | J78: =_xlfn.IFNA(VLOOKUP($D78,'Route-Details'!$B$2:$X$1048576,'Node Details'!J$1,0),"") -> 1GF | K78: 45092 | L78: 45092 | M78: WIP | W78: BAL-ANG-UASL-Mumbai-Maharashtra/PUR/100 04346 | X78: 14000 | Y78: 45181 | Z78: 102 | AF78: =IF(AB78<>"",AE78*AB78,0) -> 0 | AH78: Sudhist Enterprises | AJ78: 20 | AK78: =IF(AI78<>"",AJ78*AI78,0) -> 0 | AN78: =IF(AL78<>"",AM78*AL78,0) -> 0 | AO78: =AN78+AK78 -> 0 | AQ78: ETIL-PUR-ORD-24-06-00029 | AR78: 45461 | AS78: =AJ78 -> 20 | AT78: =AS78*AI78 -> 0 | AV78: SE/458BG | AW78: 45461 | AX78: =AJ78 -> 20 | AY78: =AI78 -> 0 | AZ78: =IF(AY78<>"",AY78*AX78,0) -> 0
A79: =A78+1 -> 77 | B79: 1GF24 | C79: R-16 | D79: 00001GF12-1GF120106 | E79: =_xlfn.IFNA(VLOOKUP($D79,'Route-Details'!$B$2:$X$1048576,'Node Details'!E$1,0),"") -> Airtel | F79: =_xlfn.IFNA(VLOOKUP($D79,'Route-Details'!$B$2:$X$1048576,'Node Details'!F$1,0),"") -> Gorai | G79: =_xlfn.IFNA(VLOOKUP($D79,'Route-Details'!$B$2:$X$1048576,'Node Details'!G$1,0),"") -> Mumbai | H79: =_xlfn.IFNA(VLOOKUP($D80,'Route-Details'!$B$2:$X$1048576,'Node Details'!H$1,0),"") -> Mumbai | I79: =_xlfn.IFNA(VLOOKUP($D79,'Route-Details'!$B$2:$X$1048576,'Node Details'!I$1,0),"") -> 1GF | J79: =_xlfn.IFNA(VLOOKUP($D79,'Route-Details'!$B$2:$X$1048576,'Node Details'!J$1,0),"") -> 1GF | K79: 45092 | L79: 45092 | M79: WIP | R79: 12F | S79: 170 | T79: 170 | U79: 170 | W79: BAL-ANG-UASL-Mumbai-Maharashtra/PUR/100 04346 | X79: 14000 | Y79: 45181 | Z79: 102 | AB79: 170 | AC79: UA | AD79: 12F | AE79: 20 | AF79: =IF(AB79<>"",AE79*AB79,0) -> 3400 | AH79: Sudhist Enterprises | AI79: 170 | AJ79: 20 | AK79: =IF(AI79<>"",AJ79*AI79,0) -> 3400 | AN79: =IF(AL79<>"",AM79*AL79,0) -> 0 | AO79: =AN79+AK79 -> 3400 | AQ79: ETIL-PUR-ORD-24-06-00029 | AR79: 45461 | AS79: =AJ79 -> 20 | AT79: =AS79*AI79 -> 3400 | AV79: SE/458BG | AW79: 45461 | AX79: =AJ79 -> 20 | AY79: =AI79 -> 170 | AZ79: =IF(AY79<>"",AY79*AX79,0) -> 3400
A80: =A79+1 -> 78 | B80: 1GF240101 | C80: R-16 | D80: 00001GF12-1GF120106 | E80: =_xlfn.IFNA(VLOOKUP($D80,'Route-Details'!$B$2:$X$1048576,'Node Details'!E$1,0),"") -> Airtel | F80: =_xlfn.IFNA(VLOOKUP($D80,'Route-Details'!$B$2:$X$1048576,'Node Details'!F$1,0),"") -> Gorai | G80: =_xlfn.IFNA(VLOOKUP($D80,'Route-Details'!$B$2:$X$1048576,'Node Details'!G$1,0),"") -> Mumbai | H80: =_xlfn.IFNA(VLOOKUP($D81,'Route-Details'!$B$2:$X$1048576,'Node Details'!H$1,0),"") -> Mumbai | I80: =_xlfn.IFNA(VLOOKUP($D80,'Route-Details'!$B$2:$X$1048576,'Node Details'!I$1,0),"") -> 1GF | J80: =_xlfn.IFNA(VLOOKUP($D80,'Route-Details'!$B$2:$X$1048576,'Node Details'!J$1,0),"") -> 1GF | K80: 45092 | L80: 45092 | M80: WIP | W80: BAL-ANG-UASL-Mumbai-Maharashtra/PUR/100 04346 | X80: 14000 | Y80: 45181 | Z80: 102 | AF80: =IF(AB80<>"",AE80*AB80,0) -> 0 | AH80: Sudhist Enterprises | AK80: =IF(AI80<>"",AJ80*AI80,0) -> 0 | AN80: =IF(AL80<>"",AM80*AL80,0) -> 0 | AO80: =AN80+AK80 -> 0 | AQ80: ETIL-PUR-ORD-24-06-00029 | AR80: 45461 | AS80: =AJ80 -> 0 | AT80: =AS80*AI80 -> 0 | AV80: SE/458BG | AW80: 45461 | AX80: =AJ80 -> 0 | AY80: =AI80 -> 0 | AZ80: =IF(AY80<>"",AY80*AX80,0) -> 0
A81: =A80+1 -> 79 | B81: 1GF240102 | C81: R-16 | D81: 00001GF12-1GF120106 | E81: =_xlfn.IFNA(VLOOKUP($D81,'Route-Details'!$B$2:$X$1048576,'Node Details'!E$1,0),"") -> Airtel | F81: =_xlfn.IFNA(VLOOKUP($D81,'Route-Details'!$B$2:$X$1048576,'Node Details'!F$1,0),"") -> Gorai | G81: =_xlfn.IFNA(VLOOKUP($D81,'Route-Details'!$B$2:$X$1048576,'Node Details'!G$1,0),"") -> Mumbai | H81: =_xlfn.IFNA(VLOOKUP($D82,'Route-Details'!$B$2:$X$1048576,'Node Details'!H$1,0),"") | I81: =_xlfn.IFNA(VLOOKUP($D81,'Route-Details'!$B$2:$X$1048576,'Node Details'!I$1,0),"") -> 1GF | J81: =_xlfn.IFNA(VLOOKUP($D81,'Route-Details'!$B$2:$X$1048576,'Node Details'!J$1,0),"") -> 1GF | K81: 45092 | L81: 45092 | M81: WIP | W81: BAL-ANG-UASL-Mumbai-Maharashtra/PUR/100 04346 | X81: 14000 | Y81: 45181 | Z81: 102 | AF81: =IF(AB81<>"",AE81*AB81,0) -> 0 | AH81: Sudhist Enterprises | AK81: =IF(AI81<>"",AJ81*AI81,0) -> 0 | AN81: =IF(AL81<>"",AM81*AL81,0) -> 0 | AO81: =AN81+AK81 -> 0 | AQ81: ETIL-PUR-ORD-24-06-00029 | AR81: 45461 | AS81: =AJ81 -> 0 | AT81: =AS81*AI81 -> 0 | AV81: SE/458BG | AW81: 45461 | AX81: =AJ81 -> 0 | AY81: =AI81 -> 0 | AZ81: =IF(AY81<>"",AY81*AX81,0) -> 0

Sheet Other Material
C1: =MATCH(C2,'Node Details'!$B$2:$U$2,0) -> 3 | D1: =MATCH(D2,'Node Details'!$B$2:$U$2,0) -> 9 | E1: =MATCH(E2,'Node Details'!$B$2:$U$2,0) -> 4 | I1: =SUBTOTAL(9,I3:I1048576) -> 912 | K1: =SUBTOTAL(9,K3:K1048576) -> 179090 | Q1: =SUBTOTAL(9,Q3:Q1048576) -> 179090
A2: Sr No | B2: FDC/FAT Unique ID | C2: Route ID (Route on which FAT/FDC is connected) | D2: Cluster ID | E2: Customer | F2: HOTO Date | H2: Item Name | I2: Qty used | J2: Rate Per Unit | K2: Total Cost | L2: Installation Date | N2: Vendor PO No | O2: Vendor PO Date | P2: Vendor PO Rate | Q2: Vendor PO Cost | S2: Vendor Invoice No | T2: Vendor Invoice Date | U2: Vendor Invoice Rate | V2: Vendor Invoiced length | W2: Invoice Amt | X2: Circle
A3: 1 | B3: 1GF120101 | C3: =IF($B3<>"",_xlfn.IFNA(VLOOKUP($B3,'Node Details'!$B:$U,C$1,0),"Check"),"") -> 00001GF12-1GF120106 | D3: =IF($B3<>"",_xlfn.IFNA(VLOOKUP($B3,'Node Details'!$B:$U,D$1,0),"Check"),"") -> 1GF | E3: =IF($B3<>"",_xlfn.IFNA(VLOOKUP($B3,'Node Details'!$B:$U,E$1,0),"Check"),"") -> Airtel | F3: 45141 | H3: Pigtail | I3: 12 | J3: 80 | K3: =IF(I3<>"",J3*I3,0) -> 960 | L3: 45141 | N3: ETIPL-PUR-ORD-23-12-00057 | O3: 45273 | P3: =J3 -> 80 | Q3: =P3*I3 -> 960 | S3: INVSR-535/23-24 | T3: 45273 | U3: =J3 -> 80 | V3: =I3 -> 12 | W3: =IF(V3<>"",V3*U3,0) -> 960 | X3: Mumbai | Y3: CCL
A4: =A3+1 -> 2 | B4: 1GF120102 | C4: =IF($B4<>"",_xlfn.IFNA(VLOOKUP($B4,'Node Details'!$B:$U,C$1,0),"Check"),"") -> 00001GF12-1GF120106 | D4: =IF($B4<>"",_xlfn.IFNA(VLOOKUP($B4,'Node Details'!$B:$U,D$1,0),"Check"),"") -> 1GF | E4: =IF($B4<>"",_xlfn.IFNA(VLOOKUP($B4,'Node Details'!$B:$U,E$1,0),"Check"),"") -> Airtel | F4: 45141 | H4: Pigtail | I4: 10 | J4: 80 | K4: =IF(I4<>"",J4*I4,0) -> 800 | L4: 45141 | N4: ETIPL-PUR-ORD-23-12-00057 | O4: 45273 | P4: =J4 -> 80 | Q4: =P4*I4 -> 800 | S4: INVSR-535/23-24 | T4: 45273 | U4: =J4 -> 80 | V4: =I4 -> 10 | W4: =IF(V4<>"",V4*U4,0) -> 800 | X4: Mumbai | Y4: CCL
A5: =A4+1 -> 3 | B5: 1GF120103 | C5: =IF($B5<>"",_xlfn.IFNA(VLOOKUP($B5,'Node Details'!$B:$U,C$1,0),"Check"),"") -> 00001GF12-1GF120106 | D5: =IF($B5<>"",_xlfn.IFNA(VLOOKUP($B5,'Node Details'!$B:$U,D$1,0),"Check"),"") -> 1GF | E5: =IF($B5<>"",_xlfn.IFNA(VLOOKUP($B5,'Node Details'!$B:$U,E$1,0),"Check"),"") -> Airtel | F5: 45141 | H5: Pigtail | I5: 10 | J5: 80 | K5: =IF(I5<>"",J5*I5,0) -> 800 | L5: 45141 | N5: ETIPL-PUR-ORD-23-12-00057 | O5: 45273 | P5: =J5 -> 80 | Q5: =P5*I5 -> 800 | S5: INVSR-535/23-24 | T5: 45273 | U5: =J5 -> 80 | V5: =I5 -> 10 | W5: =IF(V5<>"",V5*U5,0) -> 800 | X5: Mumbai | Y5: CCL
A6: =A5+1 -> 4 | B6: 1GF120104 | C6: =IF($B6<>"",_xlfn.IFNA(VLOOKUP($B6,'Node Details'!$B:$U,C$1,0),"Check"),"") -> 00001GF12-1GF120106 | D6: =IF($B6<>"",_xlfn.IFNA(VLOOKUP($B6,'Node Details'!$B:$U,D$1,0),"Check"),"") -> 1GF | E6: =IF($B6<>"",_xlfn.IFNA(VLOOKUP($B6,'Node Details'!$B:$U,E$1,0),"Check"),"") -> Airtel | F6: 45141 | H6: Pigtail | I6: 10 | J6: 80 | K6: =IF(I6<>"",J6*I6,0) -> 800 | L6: 45141 | N6: ETIPL-PUR-ORD-23-12-00057 | O6: 45273 | P6: =J6 -> 80 | Q6: =P6*I6 -> 800 | S6: INVSR-535/23-24 | T6: 45273 | U6: =J6 -> 80 | V6: =I6 -> 10 | W6: =IF(V6<>"",V6*U6,0) -> 800 | X6: Mumbai | Y6: CCL
A7: =A6+1 -> 5 | B7: 1GF120105 | C7: =IF($B7<>"",_xlfn.IFNA(VLOOKUP($B7,'Node Details'!$B:$U,C$1,0),"Check"),"") -> 00001GF12-1GF120106 | D7: =IF($B7<>"",_xlfn.IFNA(VLOOKUP($B7,'Node Details'!$B:$U,D$1,0),"Check"),"") -> 1GF | E7: =IF($B7<>"",_xlfn.IFNA(VLOOKUP($B7,'Node Details'!$B:$U,E$1,0),"Check"),"") -> Airtel | F7: 45141 | H7: Pigtail | I7: 10 | J7: 80 | K7: =IF(I7<>"",J7*I7,0) -> 800 | L7: 45141 | N7: ETIPL-PUR-ORD-23-12-00057 | O7: 45273 | P7: =J7 -> 80 | Q7: =P7*I7 -> 800 | S7: INVSR-535/23-24 | T7: 45273 | U7: =J7 -> 80 | V7: =I7 -> 10 | W7: =IF(V7<>"",V7*U7,0) -> 800 | X7: Mumbai | Y7: CCL
A8: =A7+1 -> 6 | B8: 1GF120106 | C8: =IF($B8<>"",_xlfn.IFNA(VLOOKUP($B8,'Node Details'!$B:$U,C$1,0),"Check"),"") -> 00001GF12-1GF120106 | D8: =IF($B8<>"",_xlfn.IFNA(VLOOKUP($B8,'Node Details'!$B:$U,D$1,0),"Check"),"") -> 1GF | E8: =IF($B8<>"",_xlfn.IFNA(VLOOKUP($B8,'Node Details'!$B:$U,E$1,0),"Check"),"") -> Airtel | F8: 45141 | H8: Pigtail | I8: 10 | J8: 80 | K8: =IF(I8<>"",J8*I8,0) -> 800 | L8: 45141 | N8: ETIPL-PUR-ORD-23-12-00057 | O8: 45273 | P8: =J8 -> 80 | Q8: =P8*I8 -> 800 | S8: INVSR-535/23-24 | T8: 45273 | U8: =J8 -> 80 | V8: =I8 -> 10 | W8: =IF(V8<>"",V8*U8,0) -> 800 | X8: Mumbai | Y8: CCL
A9: =A8+1 -> 7 | B9: 1GF130101 | C9: =IF($B9<>"",_xlfn.IFNA(VLOOKUP($B9,'Node Details'!$B:$U,C$1,0),"Check"),"") -> 00001GF13-1GF130106 | D9: =IF($B9<>"",_xlfn.IFNA(VLOOKUP($B9,'Node Details'!$B:$U,D$1,0),"Check"),"") -> 1GF | E9: =IF($B9<>"",_xlfn.IFNA(VLOOKUP($B9,'Node Details'!$B:$U,E$1,0),"Check"),"") -> Airtel | F9: 45141 | H9: Pigtail | I9: 12 | J9: 80 | K9: =IF(I9<>"",J9*I9,0) -> 960 | L9: 45141 | N9: ETIPL-PUR-ORD-23-12-00057 | O9: 45273 | P9: =J9 -> 80 | Q9: =P9*I9 -> 960 | S9: INVSR-535/23-24 | T9: 45273 | U9: =J9 -> 80 | V9: =I9 -> 12 | W9: =IF(V9<>"",V9*U9,0) -> 960 | X9: Mumbai | Y9: CCL
A10: =A9+1 -> 8 | B10: 1GF130102 | C10: =IF($B10<>"",_xlfn.IFNA(VLOOKUP($B10,'Node Details'!$B:$U,C$1,0),"Check"),"") -> 00001GF13-1GF130106 | D10: =IF($B10<>"",_xlfn.IFNA(VLOOKUP($B10,'Node Details'!$B:$U,D$1,0),"Check"),"") -> 1GF | E10: =IF($B10<>"",_xlfn.IFNA(VLOOKUP($B10,'Node Details'!$B:$U,E$1,0),"Check"),"") -> Airtel | F10: 45141 | H10: Pigtail | I10: 14 | J10: 80 | K10: =IF(I10<>"",J10*I10,0) -> 1120 | L10: 45141 | N10: ETIPL-PUR-ORD-23-12-00057 | O10: 45273 | P10: =J10 -> 80 | Q10: =P10*I10 -> 1120 | S10: INVSR-535/23-24 | T10: 45273 | U10: =J10 -> 80 | V10: =I10 -> 14 | W10: =IF(V10<>"",V10*U10,0) -> 1120 | X10: Mumbai | Y10: CCL
A11: =A10+1 -> 9 | B11: 1GF130103 | C11: =IF($B11<>"",_xlfn.IFNA(VLOOKUP($B11,'Node Details'!$B:$U,C$1,0),"Check"),"") -> 00001GF13-1GF130106 | D11: =IF($B11<>"",_xlfn.IFNA(VLOOKUP($B11,'Node Details'!$B:$U,D$1,0),"Check"),"") -> 1GF | E11: =IF($B11<>"",_xlfn.IFNA(VLOOKUP($B11,'Node Details'!$B:$U,E$1,0),"Check"),"") -> Airtel | F11: 45141 | H11: Pigtail | I11: 10 | J11: 80 | K11: =IF(I11<>"",J11*I11,0) -> 800 | L11: 45141 | N11: ETIPL-PUR-ORD-23-12-00057 | O11: 45273 | P11: =J11 -> 80 | Q11: =P11*I11 -> 800 | S11: INVSR-535/23-24 | T11: 45273 | U11: =J11 -> 80 | V11: =I11 -> 10 | W11: =IF(V11<>"",V11*U11,0) -> 800 | X11: Mumbai | Y11: CCL
