Workbook

Sheet Terminologies

Sheet Instructions
A1: Sr No | B1: Particulars
A2: 1 | B2: Each Region will have a unique Area Name, OLT ID & Cluster ID.
A3: =A2+1 -> 2 | B3: Every FAT/OLD/FDC/JC will have a unique ID.
A4: =A3+1 -> 3 | B4: Each entity as mentioned in above pt, will have a separate row & respective entry in the tracker | R4: Item Name
A5: =A4+1 -> 4 | B5: Kindly refer Terminologies sheet for model understanding. Alternatively you can also use respective SLDs for the same | R5: FDC
A6: =A5+1 -> 5 | B6: For filling the trackers, regional teams will have to fill cells where Headings are not highlighted. | R6: FAT Box
A7: =A6+1 -> 6 | B7: Central Team will be filling data for cells where Headings are highlighted in Yellow | R7: Duct
A8: =A7+1 -> 7 | B8: Kindly do not fill any cell where headings are highlighted in Green. | R8: Primary Splitter
A9: =A8+1 -> 8 | B9: For all FAT/FDC there will be an entry of separate row in "Node Details" sheet.
A10: =A9+1 -> 9 | B10: Any extension of current path,route will be treated as a new route.
A11: =A10+1 -> 10 | B11: Any new branch getting deployed from same common FAT/FDC which is not part of existing route shall be treated as a New Route.
A12: =A11+1 -> 11 | B12: Fiber Material & Fiber Execution service details are to be entered in "Route Details" & "Node Details" sheet only.
A13: =A12+1 -> 12 | B13: Tracker has to be filled all routes that are RFS/Deployed irrespective of Sign-off.
A14: =A13+1 -> 13 | B14: Billing start date will be HOTO date, when penetration % is >=50% | R14: Secondary Splitter
A15: =A14+1 -> 14 | B15: Kindly enter date in DD_MMM_YYYY format for all columns where date has to be entered. | R15: Pigtail
A16: =A15+1 -> 15 | B16: Kindly do not alter format of the sheet, i.e add or delete rows/columns or do any formatting changes. | R16: Patch Cords
R17: Tiffin Box
R18: FMS

Sheet Route-Details
O1: =SUBTOTAL(9,O3:O1048576) -> 38662 | W1: =SUBTOTAL(9,W3:W1048576) -> 38662 | X1: =SUBTOTAL(9,X3:X1048576) -> 37231 | AE1: =SUBTOTAL(9,AE3:AE1048576) -> 38662 | AL1: =SUBTOTAL(9,AL3:AL1048576) -> 37231 | BB1: =SUBTOTAL(9,BB3:BB1048576) -> 37231 | BC1: =SUBTOTAL(9,BC3:BC1048576) -> 694861
A2: Sr No | B2: Unique Route ID | C2: FDC/FAT Unique ID (Start Point) | D2: Start point Latlong | E2: FDC/FAT Unique ID (End Point) | F2: End point Latlong | G2: Customer | H2: Area Name | I2: City | J2: Telecom Circle | K2: State | L2: OLT ID | M2: Cluster ID | N2: Online AT Date (Delivered) | O2: Online AT Length (Delivered) | P2: HOTO Date | Q2: HOTO Signoff Date | R2: Start Date (Date from which we can bill) | S2: Lock-in Period | T2: Surrender Date | U2: Fresh Delivery/Renewal | V2: Fiber Capacity | W2: OTDR length (in meters) | X2: Customer Billable length (in meters) | Z2: Customer PO no | AA2: PO length | AB2: PO Date | AC2: PO Rate | AE2: Fiber length deployed/used (in meters) | AF2: Fiber Type | AG2: Fiber Capacity | AH2: Fiber Rate per meter (incl Freight) | AI2: Fiber Material Cost | AK2: Execution Vendor Name | AL2: Vendor Billable Length (Fiber laying) | AM2: Fiber Laying Rate | AN2: Fiber Laying/Execution Cost | AO2: OTM Length | AP2: OTM Execution Rate | AQ2: OTM Cost | AR2: Total Vendor Cost | AT2: Vendor PO No | AU2: Vendor PO Date | AV2: Vendor PO Rate | AW2: Vendor PO Cost | AY2: Vendor Invoice No | AZ2: Vendor Invoice Date | BA2: Vendor Invoice Rate | BB2: Vendor Invoiced length | BC2: Invoice Amt | BE2: Route no | BF2: Unique Route ID | BG2: Remark | BH2: Remark2
A3: 1 | B3: 000000AXZ-0000AXZ01 | C3: AXZ | E3: AXZ01 | G3: Airtel | H3: DARIA | I3: Chandigarh | J3: Punjab | K3: Chandigarh | L3: AXZ | M3: AXZ | N3: 46110 | O3: 223 | P3: 46110 | Q3: 46119 | R3: 46110 | U3: Fresh | V3: 24F | W3: 223 | X3: 172 | Z3: PO awaited | AC3: 30.5 | AE3: 223 | AF3: UA | AG3: 24F | AH3: 24.5 | AI3: =IF(AE3<>"",AH3*AE3,0) -> 5463.5 | AK3: DROR Services Private Limited | AL3: 172 | AM3: 18 | AN3: =IF(AL3<>"",AM3*AL3,0) -> 3096 | AQ3: =IF(AO3<>"",AP3*AO3,0) -> 0 | AR3: =AQ3+AN3 -> 3096 | AT3: ET-PO-PUN-2604-0017 | AU3: 46141 | AV3: =AM3 -> 18 | AW3: =AV3*AL3 -> 3096 | AY3: DSHR/2026-27/131 | AZ3: 46153 | BA3: =AM3 -> 18 | BB3: =AL3 -> 172 | BC3: =IF(BB3<>"",BB3*BA3,0) -> 3096 | BE3: R-1 | BF3: 000000AXZ-0000AXZ01 | BG3: FY 2025-26 H2 Data
A4: =A3+1 -> 2 | B4: 000000AXZ-0000AXZ03 | C4: AXZ | E4: AXZ03 | G4: Airtel | H4: DARIA | I4: Chandigarh | J4: Punjab | K4: Chandigarh | L4: AXZ | M4: AXZ | N4: 46110 | O4: 362 | P4: 46110 | Q4: 46119 | R4: 46110 | U4: Fresh | V4: 24F | W4: 362 | X4: 300 | Z4: PO awaited | AC4: 30.5 | AE4: 362 | AF4: UA | AG4: 24F | AH4: 24.5 | AI4: =IF(AE4<>"",AH4*AE4,0) -> 8869 | AK4: DROR Services Private Limited | AL4: 300 | AM4: 18 | AN4: =IF(AL4<>"",AM4*AL4,0) -> 5400 | AQ4: =IF(AO4<>"",AP4*AO4,0) -> 0 | AR4: =AQ4+AN4 -> 5400 | AT4: ET-PO-PUN-2604-0017 | AU4: 46141 | AV4: =AM4 -> 18 | AW4: =AV4*AL4 -> 5400 | AY4: DSHR/2026-27/131 | AZ4: 46153 | BA4: =AM4 -> 18 | BB4: =AL4 -> 300 | BC4: =IF(BB4<>"",BB4*BA4,0) -> 5400 | BE4: R-2 | BF4: 000000AXZ-0000AXZ03 | BG4: FY 2025-26 H2 Data
A5: =A4+1 -> 3 | B5: 0000AXZ01-AXZ010101 | C5: AXZ01 | E5: AXZ010101 | G5: Airtel | H5: DARIA | I5: Chandigarh | J5: Punjab | K5: Chandigarh | L5: AXZ | M5: AXZ | N5: 46110 | O5: 10 | P5: 46110 | Q5: 46119 | R5: 46110 | U5: Fresh | V5: 12F | W5: 10 | X5: 10 | Z5: PO awaited | AC5: 25.5 | AE5: 10 | AF5: UA | AG5: 12F | AH5: 12.5 | AI5: =IF(AE5<>"",AH5*AE5,0) -> 125 | AK5: DROR Services Private Limited | AL5: 10 | AM5: 18 | AN5: =IF(AL5<>"",AM5*AL5,0) -> 180 | AQ5: =IF(AO5<>"",AP5*AO5,0) -> 0 | AR5: =AQ5+AN5 -> 180 | AT5: ET-PO-PUN-2604-0017 | AU5: 46141 | AV5: =AM5 -> 18 | AW5: =AV5*AL5 -> 180 | AY5: DSHR/2026-27/131 | AZ5: 46153 | BA5: =AM5 -> 18 | BB5: =AL5 -> 10 | BC5: =IF(BB5<>"",BB5*BA5,0) -> 180 | BE5: R-3 | BF5: 0000AXZ01-AXZ010101 | BG5: FY 2025-26 H2 Data
A6: =A5+1 -> 4 | B6: 0000AXZ01-AXZ010102 | C6: AXZ01 | E6: AXZ010102 | G6: Airtel | H6: DARIA | I6: Chandigarh | J6: Punjab | K6: Chandigarh | L6: AXZ | M6: AXZ | N6: 46110 | O6: 217 | P6: 46110 | Q6: 46119 | R6: 46110 | U6: Fresh | V6: 12F | W6: 217 | X6: 214 | Z6: PO awaited | AC6: 25.5 | AE6: 217 | AF6: UA | AG6: 12F | AH6: 12.5 | AI6: =IF(AE6<>"",AH6*AE6,0) -> 2712.5 | AK6: DROR Services Private Limited | AL6: 214 | AM6: 18 | AN6: =IF(AL6<>"",AM6*AL6,0) -> 3852 | AQ6: =IF(AO6<>"",AP6*AO6,0) -> 0 | AR6: =AQ6+AN6 -> 3852 | AT6: ET-PO-PUN-2604-0017 | AU6: 46141 | AV6: =AM6 -> 18 | AW6: =AV6*AL6 -> 3852 | AY6: DSHR/2026-27/131 | AZ6: 46153 | BA6: =AM6 -> 18 | BB6: =AL6 -> 214 | BC6: =IF(BB6<>"",BB6*BA6,0) -> 3852 | BE6: R-4 | BF6: 0000AXZ01-AXZ010102 | BG6: FY 2025-26 H2 Data
A7: =A6+1 -> 5 | B7: 0000AXZ01-AXZ010105 | C7: AXZ01 | E7: AXZ010105 | G7: Airtel | H7: DARIA | I7: Chandigarh | J7: Punjab | K7: Chandigarh | L7: AXZ | M7: AXZ | N7: 46110 | O7: 233 | P7: 46110 | Q7: 46119 | R7: 46110 | U7: Fresh | V7: 12F | W7: 233 | X7: 224 | Z7: PO awaited | AC7: 25.5 | AE7: 233 | AF7: UA | AG7: 12F | AH7: 12.5 | AI7: =IF(AE7<>"",AH7*AE7,0) -> 2912.5 | AK7: DROR Services Private Limited | AL7: 224 | AM7: 18 | AN7: =IF(AL7<>"",AM7*AL7,0) -> 4032 | AQ7: =IF(AO7<>"",AP7*AO7,0) -> 0 | AR7: =AQ7+AN7 -> 4032 | AT7: ET-PO-PUN-2604-0017 | AU7: 46141 | AV7: =AM7 -> 18 | AW7: =AV7*AL7 -> 4032 | AY7: DSHR/2026-27/131 | AZ7: 46153 | BA7: =AM7 -> 18 | BB7: =AL7 -> 224 | BC7: =IF(BB7<>"",BB7*BA7,0) -> 4032 | BE7: R-5 | BF7: 0000AXZ01-AXZ010105 | BG7: FY 2025-26 H2 Data
A8: =A7+1 -> 6 | B8: 0000AXZ01-AXZ010202 | C8: AXZ01 | E8: AXZ010202 | G8: Airtel | H8: DARIA | I8: Chandigarh | J8: Punjab | K8: Chandigarh | L8: AXZ | M8: AXZ | N8: 46110 | O8: 456 | P8: 46110 | Q8: 46119 | R8: 46110 | U8: Fresh | V8: 12F | W8: 456 | X8: 441 | Z8: PO awaited | AC8: 25.5 | AE8: 456 | AF8: UA | AG8: 12F | AH8: 12.5 | AI8: =IF(AE8<>"",AH8*AE8,0) -> 5700 | AK8: DROR Services Private Limited | AL8: 441 | AM8: 18 | AN8: =IF(AL8<>"",AM8*AL8,0) -> 7938 | AQ8: =IF(AO8<>"",AP8*AO8,0) -> 0 | AR8: =AQ8+AN8 -> 7938 | AT8: ET-PO-PUN-2604-0017 | AU8: 46141 | AV8: =AM8 -> 18 | AW8: =AV8*AL8 -> 7938 | AY8: DSHR/2026-27/131 | AZ8: 46153 | BA8: =AM8 -> 18 | BB8: =AL8 -> 441 | BC8: =IF(BB8<>"",BB8*BA8,0) -> 7938 | BE8: R-6 | BF8: 0000AXZ01-AXZ010202 | BG8: FY 2025-26 H2 Data
A9: =A8+1 -> 7 | B9: 0000AXZ02-AXZ020101 | C9: AXZ02 | E9: AXZ020101 | G9: Airtel | H9: DARIA | I9: Chandigarh | J9: Punjab | K9: Chandigarh | L9: AXZ | M9: AXZ | N9: 46110 | O9: 10 | P9: 46110 | Q9: 46119 | R9: 46110 | U9: Fresh | V9: 12F | W9: 10 | X9: 10 | Z9: PO awaited | AC9: 25.5 | AE9: 10 | AF9: UA | AG9: 12F | AH9: 12.5 | AI9: =IF(AE9<>"",AH9*AE9,0) -> 125 | AK9: DROR Services Private Limited | AL9: 10 | AM9: 18 | AN9: =IF(AL9<>"",AM9*AL9,0) -> 180 | AQ9: =IF(AO9<>"",AP9*AO9,0) -> 0 | AR9: =AQ9+AN9 -> 180 | AT9: ET-PO-PUN-2604-0017 | AU9: 46141 | AV9: =AM9 -> 18 | AW9: =AV9*AL9 -> 180 | AY9: DSHR/2026-27/131 | AZ9: 46153 | BA9: =AM9 -> 18 | BB9: =AL9 -> 10 | BC9: =IF(BB9<>"",BB9*BA9,0) -> 180 | BE9: R-7 | BF9: 0000AXZ02-AXZ020101 | BG9: FY 2025-26 H2 Data
A10: =A9+1 -> 8 | B10: 0000AXZ02-AXZ020103 | C10: AXZ02 | E10: AXZ020103 | G10: Airtel | H10: DARIA | I10: Chandigarh | J10: Punjab | K10: Chandigarh | L10: AXZ | M10: AXZ | N10: 46110 | O10: 84 | P10: 46110 | Q10: 46119 | R10: 46110 | U10: Fresh | V10: 12F | W10: 84 | X10: 77 | Z10: PO awaited | AC10: 25.5 | AE10: 84 | AF10: UA | AG10: 12F | AH10: 12.5 | AI10: =IF(AE10<>"",AH10*AE10,0) -> 1050 | AK10: DROR Services Private Limited | AL10: 77 | AM10: 18 | AN10: =IF(AL10<>"",AM10*AL10,0) -> 1386 | AQ10: =IF(AO10<>"",AP10*AO10,0) -> 0 | AR10: =AQ10+AN10 -> 1386 | AT10: ET-PO-PUN-2604-0017 | AU10: 46141 | AV10: =AM10 -> 18 | AW10: =AV10*AL10 -> 1386 | AY10: DSHR/2026-27/131 | AZ10: 46153 | BA10: =AM10 -> 18 | BB10: =AL10 -> 77 | BC10: =IF(BB10<>"",BB10*BA10,0) -> 1386 | BE10: R-8 | BF10: 0000AXZ02-AXZ020103 | BG10: FY 2025-26 H2 Data
A11: =A10+1 -> 9 | B11: 0000AXZ02-AXZ020203 | C11: AXZ02 | E11: AXZ020203 | G11: Airtel | H11: DARIA | I11: Chandigarh | J11: Punjab | K11: Chandigarh | L11: AXZ | M11: AXZ | N11: 46110 | O11: 445 | P11: 46110 | Q11: 46119 | R11: 46110 | U11: Fresh | V11: 12F | W11: 445 | X11: 420 | Z11: PO awaited | AC11: 25.5 | AE11: 445 | AF11: UA | AG11: 12F | AH11: 12.5 | AI11: =IF(AE11<>"",AH11*AE11,0) -> 5562.5 | AK11: DROR Services Private Limited | AL11: 420 | AM11: 18 | AN11: =IF(AL11<>"",AM11*AL11,0) -> 7560 | AQ11: =IF(AO11<>"",AP11*AO11,0) -> 0 | AR11: =AQ11+AN11 -> 7560 | AT11: ET-PO-PUN-2604-0017 | AU11: 46141 | AV11: =AM11 -> 18 | AW11: =AV11*AL11 -> 7560 | AY11: DSHR/2026-27/131 | AZ11: 46153 | BA11: =AM11 -> 18 | BB11: =AL11 -> 420 | BC11: =IF(BB11<>"",BB11*BA11,0) -> 7560 | BE11: R-9 | BF11: 0000AXZ02-AXZ020203 | BG11: FY 2025-26 H2 Data
A12: =A11+1 -> 10 | B12: 0000AXZ03-AXZ030101 | C12: AXZ03 | E12: AXZ030101 | G12: Airtel | H12: DARIA | I12: Chandigarh | J12: Punjab | K12: Chandigarh | L12: AXZ | M12: AXZ | N12: 46110 | O12: 10 | P12: 46110 | Q12: 46119 | R12: 46110 | U12: Fresh | V12: 12F | W12: 10 | X12: 10 | Z12: PO awaited | AC12: 25.5 | AE12: 10 | AF12: UA | AG12: 12F | AH12: 12.5 | AI12: =IF(AE12<>"",AH12*AE12,0) -> 125 | AK12: DROR Services Private Limited | AL12: 10 | AM12: 18 | AN12: =IF(AL12<>"",AM12*AL12,0) -> 180 | AQ12: =IF(AO12<>"",AP12*AO12,0) -> 0 | AR12: =AQ12+AN12 -> 180 | AT12: ET-PO-PUN-2604-0017 | AU12: 46141 | AV12: =AM12 -> 18 | AW12: =AV12*AL12 -> 180 | AY12: DSHR/2026-27/131 | AZ12: 46153 | BA12: =AM12 -> 18 | BB12: =AL12 -> 10 | BC12: =IF(BB12<>"",BB12*BA12,0) -> 180 | BE12: R-10 | BF12: 0000AXZ03-AXZ030101 | BG12: FY 2025-26 H2 Data
A13: =A12+1 -> 11 | B13: 0000AXZ03-AXZ030102 | C13: AXZ03 | E13: AXZ030102 | G13: Airtel | H13: DARIA | I13: Chandigarh | J13: Punjab | K13: Chandigarh | L13: AXZ | M13: AXZ | N13: 46110 | O13: 50 | P13: 46110 | Q13: 46119 | R13: 46110 | U13: Fresh | V13: 24F | W13: 50 | X13: 39 | Z13: PO awaited | AC13: 30.5 | AE13: 50 | AF13: UA | AG13: 24F | AH13: 24.5 | AI13: =IF(AE13<>"",AH13*AE13,0) -> 1225 | AK13: DROR Services Private Limited | AL13: 39 | AM13: 18 | AN13: =IF(AL13<>"",AM13*AL13,0) -> 702 | AQ13: =IF(AO13<>"",AP13*AO13,0) -> 0 | AR13: =AQ13+AN13 -> 702 | AT13: ET-PO-PUN-2604-0017 | AU13: 46141 | AV13: =AM13 -> 18 | AW13: =AV13*AL13 -> 702 | AY13: DSHR/2026-27/131 | AZ13: 46153 | BA13: =AM13 -> 18 | BB13: =AL13 -> 39 | BC13: =IF(BB13<>"",BB13*BA13,0) -> 702 | BE13: R-11 | BF13: 0000AXZ03-AXZ030102 | BG13: FY 2025-26 H2 Data
A14: =A13+1 -> 12 | B14: 0000AXZ03-AXZ030104 | C14: AXZ03 | E14: AXZ030104 | G14: Airtel | H14: DARIA | I14: Chandigarh | J14: Punjab | K14: Chandigarh | L14: AXZ | M14: AXZ | N14: 46110 | O14: 152 | P14: 46110 | Q14: 46119 | R14: 46110 | U14: Fresh | V14: 24F | W14: 152 | X14: 130 | Z14: PO awaited | AC14: 30.5 | AE14: 152 | AF14: UA | AG14: 24F | AH14: 24.5 | AI14: =IF(AE14<>"",AH14*AE14,0) -> 3724 | AK14: DROR Services Private Limited | AL14: 130 | AM14: 18 | AN14: =IF(AL14<>"",AM14*AL14,0) -> 2340 | AQ14: =IF(AO14<>"",AP14*AO14,0) -> 0 | AR14: =AQ14+AN14 -> 2340 | AT14: ET-PO-PUN-2604-0017 | AU14: 46141 | AV14: =AM14 -> 18 | AW14: =AV14*AL14 -> 2340 | AY14: DSHR/2026-27/131 | AZ14: 46153 | BA14: =AM14 -> 18 | BB14: =AL14 -> 130 | BC14: =IF(BB14<>"",BB14*BA14,0) -> 2340 | BE14: R-12 | BF14: 0000AXZ03-AXZ030104 | BG14: FY 2025-26 H2 Data
A15: =A14+1 -> 13 | B15: AXZ030104-AXZ030106 | C15: AXZ030104 | E15: AXZ030106 | G15: Airtel | H15: DARIA | I15: Chandigarh | J15: Punjab | K15: Chandigarh | L15: AXZ | M15: AXZ | N15: 46110 | O15: 213 | P15: 46110 | Q15: 46119 | R15: 46110 | U15: Fresh | V15: 24F | W15: 213 | X15: 176 | Z15: PO awaited | AC15: 30.5 | AE15: 213 | AF15: UA | AG15: 24F | AH15: 24.5 | AI15: =IF(AE15<>"",AH15*AE15,0) -> 5218.5 | AK15: DROR Services Private Limited | AL15: 176 | AM15: 18 | AN15: =IF(AL15<>"",AM15*AL15,0) -> 3168 | AQ15: =IF(AO15<>"",AP15*AO15,0) -> 0 | AR15: =AQ15+AN15 -> 3168 | AT15: ET-PO-PUN-2604-0017 | AU15: 46141 | AV15: =AM15 -> 18 | AW15: =AV15*AL15 -> 3168 | AY15: DSHR/2026-27/131 | AZ15: 46153 | BA15: =AM15 -> 18 | BB15: =AL15 -> 176 | BC15: =IF(BB15<>"",BB15*BA15,0) -> 3168 | BE15: R-15 | BF15: AXZ030104-AXZ030106 | BG15: FY 2025-26 H2 Data
... A17: =A16+1 -> 15 | B17: AXZ030201-AXZ030205 | C17: AXZ030201 | E17: AXZ030205 | G17: Airtel | H17: DARIA | I17: Chandigarh | J17: Punjab | K17: Chandigarh | L17: AXZ | M17: AXZ | N17: 46110 | O17: 88 | P17: 46110 | Q17: 46119 | R17: 46110 | U17: Fresh | V17: 12F | W17: 88 | X17: 82 | Z17: PO awaited | AC17: 25.5 | AE17: 88 | AF17: UA | AG17: 12F | AH17: 12.5 | AI17: =IF(AE17<>"",AH17*AE17,0) -> 1100 | AK17: DROR Services Private Limited | AL17: 82 | AM17: 18 | AN17: =IF(AL17<>"",AM17*AL17,0) -> 1476 | AQ17: =IF(AO17<>"",AP17*AO17,0) -> 0 | AR17: =AQ17+AN17 -> 1476 | AT17: ET-PO-PUN-2604-0017 | AU17: 46141 | AV17: =AM17 -> 18 | AW17: =AV17*AL17 -> 1476 | AY17: DSHR/2026-27/131 | AZ17: 46153 | BA17: =AM17 -> 18 | BB17: =AL17 -> 82 | BC17: =IF(BB17<>"",BB17*BA17,0) -> 1476 | BE17: R-14 | BF17: AXZ030201-AXZ030205 | BG17: FY 2025-26 H2 Data
A18: =A17+1 -> 16 | B18: 000000AXY-0000AXY12 | C18: AXY | E18: AXY12 | G18: Airtel | H18: DARIA | I18: Chandigarh | J18: Punjab | K18: Chandigarh | L18: AXY | M18: AXY | N18: 46112 | O18: 931 | P18: 46113 | Q18: 46125 | R18: 46113 | U18: Fresh | V18: 48F | W18: 931 | X18: 811 | Z18: PO awaited | AC18: 35.5 | AE18: 931 | AF18: UA | AG18: 48F | AH18: 38.5 | AI18: =IF(AE18<>"",AH18*AE18,0) -> 35843.5 | AK18: DROR Services Private Limited | AL18: 811 | AM18: 20 | AN18: =IF(AL18<>"",AM18*AL18,0) -> 16220 | AQ18: =IF(AO18<>"",AP18*AO18,0) -> 0 | AR18: =AQ18+AN18 -> 16220 | AT18: ET-PO-PUN-2604-0016 | AU18: 46141 | AV18: =AM18 -> 20 | AW18: =AV18*AL18 -> 16220 | AY18: Invoice Awaited | BA18: =AM18 -> 20 | BB18: =AL18 -> 811 | BC18: =IF(BB18<>"",BB18*BA18,0) -> 16220 | BE18: R-1 | BF18: 000000AXY-0000AXY12 | BG18: FY 2025-26 H2 Data | BH18: Consumption and RFS done in March 2026 but signoff done in April 2026
A19: =A18+1 -> 17 | B19: 000000AXY-0000AXY17 | C19: AXY | E19: AXY17 | G19: Airtel | H19: DARIA | I19: Chandigarh | J19: Punjab | K19: Chandigarh | L19: AXY | M19: AXY | N19: 46112 | O19: 654 | P19: 46113 | Q19: 46125 | R19: 46113 | U19: Fresh | V19: 48F | W19: 654 | X19: 589 | Z19: PO awaited | AC19: 35.5 | AE19: 654 | AF19: UA | AG19: 48F | AH19: 38.5 | AI19: =IF(AE19<>"",AH19*AE19,0) -> 25179 | AK19: DROR Services Private Limited | AL19: 589 | AM19: 20 | AN19: =IF(AL19<>"",AM19*AL19,0) -> 11780 | AQ19: =IF(AO19<>"",AP19*AO19,0) -> 0 | AR19: =AQ19+AN19 -> 11780 | AT19: ET-PO-PUN-2604-0016 | AU19: 46141 | AV19: =AM19 -> 20 | AW19: =AV19*AL19 -> 11780 | AY19: Invoice Awaited | BA19: =AM19 -> 20 | BB19: =AL19 -> 589 | BC19: =IF(BB19<>"",BB19*BA19,0) -> 11780 | BE19: R-2 | BF19: 000000AXY-0000AXY17 | BG19: FY 2025-26 H2 Data | BH19: Consumption and RFS done in March 2026 but signoff done in April 2026
A20: =A19+1 -> 18 | B20: 000000AXY-0000AXY01 | C20: AXY | E20: AXY01 | G20: Airtel | H20: DARIA | I20: Chandigarh | J20: Punjab | K20: Chandigarh | L20: AXY | M20: AXY | N20: 46112 | O20: 129 | P20: 46113 | Q20: 46125 | R20: 46113 | U20: Fresh | V20: 24F | W20: 129 | X20: 128 | Z20: PO awaited | AC20: 30.5 | AE20: 129 | AF20: UA | AG20: 24F | AH20: 24.5 | AI20: =IF(AE20<>"",AH20*AE20,0) -> 3160.5 | AK20: DROR Services Private Limited | AL20: 128 | AM20: 18 | AN20: =IF(AL20<>"",AM20*AL20,0) -> 2304 | AQ20: =IF(AO20<>"",AP20*AO20,0) -> 0 | AR20: =AQ20+AN20 -> 2304 | AT20: ET-PO-PUN-2604-0016 | AU20: 46141 | AV20: =AM20 -> 18 | AW20: =AV20*AL20 -> 2304 | AY20: Invoice Awaited | BA20: =AM20 -> 18 | BB20: =AL20 -> 128 | BC20: =IF(BB20<>"",BB20*BA20,0) -> 2304 | BE20: R-3 | BF20: 000000AXY-0000AXY01 | BG20: FY 2025-26 H2 Data | BH20: Consumption and RFS done in March 2026 but signoff done in April 2026
A21: =A20+1 -> 19 | B21: 0000AXY04-0000AXY05 | C21: AXY04 | E21: AXY05 | G21: Airtel | H21: DARIA | I21: Chandigarh | J21: Punjab | K21: Chandigarh | L21: AXY | M21: AXY | N21: 46112 | O21: 109 | P21: 46113 | Q21: 46125 | R21: 46113 | U21: Fresh | V21: 24F | W21: 109 | X21: 110 | Z21: PO awaited | AC21: 30.5 | AE21: 109 | AF21: UA | AG21: 24F | AH21: 24.5 | AI21: =IF(AE21<>"",AH21*AE21,0) -> 2670.5 | AK21: DROR Services Private Limited | AL21: 110 | AM21: 18 | AN21: =IF(AL21<>"",AM21*AL21,0) -> 1980 | AQ21: =IF(AO21<>"",AP21*AO21,0) -> 0 | AR21: =AQ21+AN21 -> 1980 | AT21: ET-PO-PUN-2604-0016 | AU21: 46141 | AV21: =AM21 -> 18 | AW21: =AV21*AL21 -> 1980 | AY21: Invoice Awaited | BA21: =AM21 -> 18 | BB21: =AL21 -> 110 | BC21: =IF(BB21<>"",BB21*BA21,0) -> 1980 | BE21: R-4 | BF21: 0000AXY04-0000AXY05 | BG21: FY 2025-26 H2 Data | BH21: Consumption and RFS done in March 2026 but signoff done in April 2026
A22: =A21+1 -> 20 | B22: 0000AXY02-0000AXY03 | C22: AXY02 | E22: AXY03 | G22: Airtel | H22: DARIA | I22: Chandigarh | J22: Punjab | K22: Chandigarh | L22: AXY | M22: AXY | N22: 46112 | O22: 62 | P22: 46113 | Q22: 46125 | R22: 46113 | U22: Fresh | V22: 24F | W22: 62 | X22: 62 | Z22: PO awaited | AC22: 30.5 | AE22: 62 | AF22: UA | AG22: 24F | AH22: 24.5 | AI22: =IF(AE22<>"",AH22*AE22,0) -> 1519 | AK22: DROR Services Private Limited | AL22: 62 | AM22: 18 | AN22: =IF(AL22<>"",AM22*AL22,0) -> 1116 | AQ22: =IF(AO22<>"",AP22*AO22,0) -> 0 | AR22: =AQ22+AN22 -> 1116 | AT22: ET-PO-PUN-2604-0016 | AU22: 46141 | AV22: =AM22 -> 18 | AW22: =AV22*AL22 -> 1116 | AY22: Invoice Awaited | BA22: =AM22 -> 18 | BB22: =AL22 -> 62 | BC22: =IF(BB22<>"",BB22*BA22,0) -> 1116 | BE22: R-5 | BF22: 0000AXY02-0000AXY03 | BG22: FY 2025-26 H2 Data | BH22: Consumption and RFS done in March 2026 but signoff done in April 2026
A23: =A22+1 -> 21 | B23: 0000AXY01-AXY010101 | C23: AXY01 | E23: AXY010101 | G23: Airtel | H23: DARIA | I23: Chandigarh | J23: Punjab | K23: Chandigarh | L23: AXY | M23: AXY | N23: 46112 | O23: 10 | P23: 46113 | Q23: 46125 | R23: 46113 | U23: Fresh | V23: 12F | W23: 10 | X23: 10 | Z23: PO awaited | AC23: 25.5 | AE23: 10 | AF23: UA | AG23: 12F | AH23: 12.5 | AI23: =IF(AE23<>"",AH23*AE23,0) -> 125 | AK23: DROR Services Private Limited | AL23: 10 | AM23: 18 | AN23: =IF(AL23<>"",AM23*AL23,0) -> 180 | AQ23: =IF(AO23<>"",AP23*AO23,0) -> 0 | AR23: =AQ23+AN23 -> 180 | AT23: ET-PO-PUN-2604-0016 | AU23: 46141 | AV23: =AM23 -> 18 | AW23: =AV23*AL23 -> 180 | AY23: Invoice Awaited | BA23: =AM23 -> 18 | BB23: =AL23 -> 10 | BC23: =IF(BB23<>"",BB23*BA23,0) -> 180 | BE23: R-6 | BF23: 0000AXY01-AXY010101 | BG23: FY 2025-26 H2 Data | BH23: Consumption and RFS done in March 2026 but signoff done in April 2026
A24: =A23+1 -> 22 | B24: 0000AXY01-AXY010104 | C24: AXY01 | E24: AXY010104 | G24: Airtel | H24: DARIA | I24: Chandigarh | J24: Punjab | K24: Chandigarh | L24: AXY | M24: AXY | N24: 46112 | O24: 114 | P24: 46113 | Q24: 46125 | R24: 46113 | U24: Fresh | V24: 12F | W24: 114 | X24: 106 | Z24: PO awaited | AC24: 25.5 | AE24: 114 | AF24: UA | AG24: 12F | AH24: 12.5 | AI24: =IF(AE24<>"",AH24*AE24,0) -> 1425 | AK24: DROR Services Private Limited | AL24: 106 | AM24: 18 | AN24: =IF(AL24<>"",AM24*AL24,0) -> 1908 | AQ24: =IF(AO24<>"",AP24*AO24,0) -> 0 | AR24: =AQ24+AN24 -> 1908 | AT24: ET-PO-PUN-2604-0016 | AU24: 46141 | AV24: =AM24 -> 18 | AW24: =AV24*AL24 -> 1908 | AY24: Invoice Awaited | BA24: =AM24 -> 18 | BB24: =AL24 -> 106 | BC24: =IF(BB24<>"",BB24*BA24,0) -> 1908 | BE24: R-7 | BF24: 0000AXY01-AXY010104 | BG24: FY 2025-26 H2 Data | BH24: Consumption and RFS done in March 2026 but signoff done in April 2026
A25: =A24+1 -> 23 | B25: 0000AXY01-AXY010102 | C25: AXY01 | E25: AXY010102 | G25: Airtel | H25: DARIA | I25: Chandigarh | J25: Punjab | K25: Chandigarh | L25: AXY | M25: AXY | N25: 46112 | O25: 31 | P25: 46113 | Q25: 46125 | R25: 46113 | U25: Fresh | V25: 12F | W25: 31 | X25: 26 | Z25: PO awaited | AC25: 25.5 | AE25: 31 | AF25: UA | AG25: 12F | AH25: 12.5 | AI25: =IF(AE25<>"",AH25*AE25,0) -> 387.5 | AK25: DROR Services Private Limited | AL25: 26 | AM25: 18 | AN25: =IF(AL25<>"",AM25*AL25,0) -> 468 | AQ25: =IF(AO25<>"",AP25*AO25,0) -> 0 | AR25: =AQ25+AN25 -> 468 | AT25: ET-PO-PUN-2604-0016 | AU25: 46141 | AV25: =AM25 -> 18 | AW25: =AV25*AL25 -> 468 | AY25: Invoice Awaited | BA25: =AM25 -> 18 | BB25: =AL25 -> 26 | BC25: =IF(BB25<>"",BB25*BA25,0) -> 468 | BE25: R-8 | BF25: 0000AXY01-AXY010102 | BG25: FY 2025-26 H2 Data | BH25: Consumption and RFS done in March 2026 but signoff done in April 2026
A26: =A25+1 -> 24 | B26: 0000AXY03-AXY030101 | C26: AXY03 | E26: AXY030101 | G26: Airtel | H26: DARIA | I26: Chandigarh | J26: Punjab | K26: Chandigarh | L26: AXY | M26: AXY | N26: 46112 | O26: 10 | P26: 46113 | Q26: 46125 | R26: 46113 | U26: Fresh | V26: 12F | W26: 10 | X26: 10 | Z26: PO awaited | AC26: 25.5 | AE26: 10 | AF26: UA | AG26: 12F | AH26: 12.5 | AI26: =IF(AE26<>"",AH26*AE26,0) -> 125 | AK26: DROR Services Private Limited | AL26: 10 | AM26: 18 | AN26: =IF(AL26<>"",AM26*AL26,0) -> 180 | AQ26: =IF(AO26<>"",AP26*AO26,0) -> 0 | AR26: =AQ26+AN26 -> 180 | AT26: ET-PO-PUN-2604-0016 | AU26: 46141 | AV26: =AM26 -> 18 | AW26: =AV26*AL26 -> 180 | AY26: Invoice Awaited | BA26: =AM26 -> 18 | BB26: =AL26 -> 10 | BC26: =IF(BB26<>"",BB26*BA26,0) -> 180 | BE26: R-9 | BF26: 0000AXY03-AXY030101 | BG26: FY 2025-26 H2 Data | BH26: Consumption and RFS done in March 2026 but signoff done in April 2026
A27: =A26+1 -> 25 | B27: 0000AXY03-AXY030104 | C27: AXY03 | E27: AXY030104 | G27: Airtel | H27: DARIA | I27: Chandigarh | J27: Punjab | K27: Chandigarh | L27: AXY | M27: AXY | N27: 46112 | O27: 122 | P27: 46113 | Q27: 46125 | R27: 46113 | U27: Fresh | V27: 12F | W27: 122 | X27: 112 | Z27: PO awaited | AC27: 25.5 | AE27: 122 | AF27: UA | AG27: 12F | AH27: 12.5 | AI27: =IF(AE27<>"",AH27*AE27,0) -> 1525 | AK27: DROR Services Private Limited | AL27: 112 | AM27: 18 | AN27: =IF(AL27<>"",AM27*AL27,0) -> 2016 | AQ27: =IF(AO27<>"",AP27*AO27,0) -> 0 | AR27: =AQ27+AN27 -> 2016 | AT27: ET-PO-PUN-2604-0016 | AU27: 46141 | AV27: =AM27 -> 18 | AW27: =AV27*AL27 -> 2016 | AY27: Invoice Awaited | BA27: =AM27 -> 18 | BB27: =AL27 -> 112 | BC27: =IF(BB27<>"",BB27*BA27,0) -> 2016 | BE27: R-10 | BF27: 0000AXY03-AXY030104 | BG27: FY 2025-26 H2 Data | BH27: Consumption and RFS done in March 2026 but signoff done in April 2026
A28: =A27+1 -> 26 | B28: AXY030103-AXY030105 | C28: AXY030103 | E28: AXY030105 | G28: Airtel | H28: DARIA | I28: Chandigarh | J28: Punjab | K28: Chandigarh | L28: AXY | M28: AXY | N28: 46112 | O28: 33 | P28: 46113 | Q28: 46125 | R28: 46113 | U28: Fresh | V28: 12F | W28: 33 | X28: 28 | Z28: PO awaited | AC28: 25.5 | AE28: 33 | AF28: UA | AG28: 12F | AH28: 12.5 | AI28: =IF(AE28<>"",AH28*AE28,0) -> 412.5 | AK28: DROR Services Private Limited | AL28: 28 | AM28: 18 | AN28: =IF(AL28<>"",AM28*AL28,0) -> 504 | AQ28: =IF(AO28<>"",AP28*AO28,0) -> 0 | AR28: =AQ28+AN28 -> 504 | AT28: ET-PO-PUN-2604-0016 | AU28: 46141 | AV28: =AM28 -> 18 | AW28: =AV28*AL28 -> 504 | AY28: Invoice Awaited | BA28: =AM28 -> 18 | BB28: =AL28 -> 28 | BC28: =IF(BB28<>"",BB28*BA28,0) -> 504 | BE28: R-11 | BF28: AXY030103-AXY030105 | BG28: FY 2025-26 H2 Data | BH28: Consumption and RFS done in March 2026 but signoff done in April 2026
A29: =A28+1 -> 27 | B29: 0000AXY03-AXY030108 | C29: AXY03 | E29: AXY030108 | G29: Airtel | H29: DARIA | I29: Chandigarh | J29: Punjab | K29: Chandigarh | L29: AXY | M29: AXY | N29: 46112 | O29: 245 | P29: 46113 | Q29: 46125 | R29: 46113 | U29: Fresh | V29: 24F | W29: 245 | X29: 245 | Z29: PO awaited | AC29: 30.5 | AE29: 245 | AF29: UA | AG29: 24F | AH29: 24.5 | AI29: =IF(AE29<>"",AH29*AE29,0) -> 6002.5 | AK29: DROR Services Private Limited | AL29: 245 | AM29: 18 | AN29: =IF(AL29<>"",AM29*AL29,0) -> 4410 | AQ29: =IF(AO29<>"",AP29*AO29,0) -> 0 | AR29: =AQ29+AN29 -> 4410 | AT29: ET-PO-PUN-2604-0016 | AU29: 46141 | AV29: =AM29 -> 18 | AW29: =AV29*AL29 -> 4410 | AY29: Invoice Awaited | BA29: =AM29 -> 18 | BB29: =AL29 -> 245 | BC29: =IF(BB29<>"",BB29*BA29,0) -> 4410 | BE29: R-12 | BF29: 0000AXY03-AXY030108 | BG29: FY 2025-26 H2 Data | BH29: Consumption and RFS done in March 2026 but signoff done in April 2026
... A74: =A73+1 -> 72 | B74: AXY140202-AXY140203 | C74: AXY140202 | E74: AXY140203 | G74: Airtel | H74: DARIA | I74: Chandigarh | J74: Punjab | K74: Chandigarh | L74: AXY | M74: AXY | N74: 46112 | O74: 41 | P74: 46113 | Q74: 46125 | R74: 46113 | U74: Fresh | V74: 12F | W74: 41 | X74: 39 | Z74: PO awaited | AC74: 25.5 | AE74: 41 | AF74: UA | AG74: 12F | AH74: 12.5 | AI74: =IF(AE74<>"",AH74*AE74,0) -> 512.5 | AK74: DROR Services Private Limited | AL74: 39 | AM74: 18 | AN74: =IF(AL74<>"",AM74*AL74,0) -> 702 | AQ74: =IF(AO74<>"",AP74*AO74,0) -> 0 | AR74: =AQ74+AN74 -> 702 | AT74: ET-PO-PUN-2604-0016 | AU74: 46141 | AV74: =AM74 -> 18 | AW74: =AV74*AL74 -> 702 | AY74: Invoice Awaited | BA74: =AM74 -> 18 | BB74: =AL74 -> 39 | BC74: =IF(BB74<>"",BB74*BA74,0) -> 702 | BE74: R-57 | BF74: AXY140202-AXY140203 | BG74: FY 2025-26 H2 Data | BH74: Consumption and RFS done in March 2026 but signoff done in April 2026
A75: =A74+1 -> 73 | B75: AXY140108-AXY140104 | C75: AXY140108 | E75: AXY140104 | G75: Airtel | H75: DARIA | I75: Chandigarh | J75: Punjab | K75: Chandigarh | L75: AXY | M75: AXY | N75: 46112 | O75: 178 | P75: 46113 | Q75: 46125 | R75: 46113 | U75: Fresh | V75: 12F | W75: 178 | X75: 170 | Z75: PO awaited | AC75: 25.5 | AE75: 178 | AF75: UA | AG75: 12F | AH75: 12.5 | AI75: =IF(AE75<>"",AH75*AE75,0) -> 2225 | AK75: DROR Services Private Limited | AL75: 170 | AM75: 18 | AN75: =IF(AL75<>"",AM75*AL75,0) -> 3060 | AQ75: =IF(AO75<>"",AP75*AO75,0) -> 0 | AR75: =AQ75+AN75 -> 3060 | AT75: ET-PO-PUN-2604-0016 | AU75: 46141 | AV75: =AM75 -> 18 | AW75: =AV75*AL75 -> 3060 | AY75: DSHR/2026-27/130 | AZ75: 46153 | BA75: =AM75 -> 18 | BB75: =AL75 -> 170 | BC75: =IF(BB75<>"",BB75*BA75,0) -> 3060 | BE75: R-58 | BF75: AXY140108-AXY140104 | BG75: FY 2025-26 H2 Data | BH75: Consumption and RFS done in March 2026 but signoff done in April 2026
A76: =A75+1 -> 74 | B76: 0000AXY15-AXY150103 | C76: AXY15 | E76: AXY150103 | G76: Airtel | H76: DARIA | I76: Chandigarh | J76: Punjab | K76: Chandigarh | L76: AXY | M76: AXY | N76: 46112 | O76: 131 | P76: 46113 | Q76: 46125 | R76: 46113 | U76: Fresh | V76: 12F | W76: 131 | X76: 125 | Z76: PO awaited | AC76: 25.5 | AE76: 131 | AF76: UA | AG76: 12F | AH76: 12.5 | AI76: =IF(AE76<>"",AH76*AE76,0) -> 1637.5 | AK76: DROR Services Private Limited | AL76: 125 | AM76: 18 | AN76: =IF(AL76<>"",AM76*AL76,0) -> 2250 | AQ76: =IF(AO76<>"",AP76*AO76,0) -> 0 | AR76: =AQ76+AN76 -> 2250 | AT76: ET-PO-PUN-2604-0016 | AU76: 46141 | AV76: =AM76 -> 18 | AW76: =AV76*AL76 -> 2250 | AY76: DSHR/2026-27/130 | AZ76: 46153 | BA76: =AM76 -> 18 | BB76: =AL76 -> 125 | BC76: =IF(BB76<>"",BB76*BA76,0) -> 2250 | BE76: R-59 | BF76: 0000AXY15-AXY150103 | BG76: FY 2025-26 H2 Data | BH76: Consumption and RFS done in March 2026 but signoff done in April 2026
A77: =A76+1 -> 75 | B77: 0000AXY15-AXY150104 | C77: AXY15 | E77: AXY150104 | G77: Airtel | H77: DARIA | I77: Chandigarh | J77: Punjab | K77: Chandigarh | L77: AXY | M77: AXY | N77: 46112 | O77: 10 | P77: 46113 | Q77: 46125 | R77: 46113 | U77: Fresh | V77: 12F | W77: 10 | X77: 10 | Z77: PO awaited | AC77: 25.5 | AE77: 10 | AF77: UA | AG77: 12F | AH77: 12.5 | AI77: =IF(AE77<>"",AH77*AE77,0) -> 125 | AK77: DROR Services Private Limited | AL77: 10 | AM77: 18 | AN77: =IF(AL77<>"",AM77*AL77,0) -> 180 | AQ77: =IF(AO77<>"",AP77*AO77,0) -> 0 | AR77: =AQ77+AN77 -> 180 | AT77: ET-PO-PUN-2604-0016 | AU77: 46141 | AV77: =AM77 -> 18 | AW77: =AV77*AL77 -> 180 | AY77: DSHR/2026-27/130 | AZ77: 46153 | BA77: =AM77 -> 18 | BB77: =AL77 -> 10 | BC77: =IF(BB77<>"",BB77*BA77,0) -> 180 | BE77: R-60 | BF77: 0000AXY15-AXY150104 | BG77: FY 2025-26 H2 Data | BH77: Consumption and RFS done in March 2026 but signoff done in April 2026
A78: =A77+1 -> 76 | B78: 0000AXY15-AXY150108 | C78: AXY15 | E78: AXY150108 | G78: Airtel | H78: DARIA | I78: Chandigarh | J78: Punjab | K78: Chandigarh | L78: AXY | M78: AXY | N78: 46112 | O78: 139 | P78: 46113 | Q78: 46125 | R78: 46113 | U78: Fresh | V78: 12F | W78: 139 | X78: 133 | Z78: PO awaited | AC78: 25.5 | AE78: 139 | AF78: UA | AG78: 12F | AH78: 12.5 | AI78: =IF(AE78<>"",AH78*AE78,0) -> 1737.5 | AK78: DROR Services Private Limited | AL78: 133 | AM78: 18 | AN78: =IF(AL78<>"",AM78*AL78,0) -> 2394 | AQ78: =IF(AO78<>"",AP78*AO78,0) -> 0 | AR78: =AQ78+AN78 -> 2394 | AT78: ET-PO-PUN-2604-0016 | AU78: 46141 | AV78: =AM78 -> 18 | AW78: =AV78*AL78 -> 2394 | AY78: DSHR/2026-27/130 | AZ78: 46153 | BA78: =AM78 -> 18 | BB78: =AL78 -> 133 | BC78: =IF(BB78<>"",BB78*BA78,0) -> 2394 | BE78: R-61 | BF78: 0000AXY15-AXY150108 | BG78: FY 2025-26 H2 Data | BH78: Consumption and RFS done in March 2026 but signoff done in April 2026
A79: =A78+1 -> 77 | B79: 0000AXY16-AXY160104 | C79: AXY16 | E79: AXY160104 | G79: Airtel | H79: DARIA | I79: Chandigarh | J79: Punjab | K79: Chandigarh | L79: AXY | M79: AXY | N79: 46112 | O79: 10 | P79: 46113 | Q79: 46125 | R79: 46113 | U79: Fresh | V79: 12F | W79: 10 | X79: 10 | Z79: PO awaited | AC79: 25.5 | AE79: 10 | AF79: UA | AG79: 12F | AH79: 12.5 | AI79: =IF(AE79<>"",AH79*AE79,0) -> 125 | AK79: DROR Services Private Limited | AL79: 10 | AM79: 18 | AN79: =IF(AL79<>"",AM79*AL79,0) -> 180 | AQ79: =IF(AO79<>"",AP79*AO79,0) -> 0 | AR79: =AQ79+AN79 -> 180 | AT79: ET-PO-PUN-2604-0016 | AU79: 46141 | AV79: =AM79 -> 18 | AW79: =AV79*AL79 -> 180 | AY79: DSHR/2026-27/130 | AZ79: 46153 | BA79: =AM79 -> 18 | BB79: =AL79 -> 10 | BC79: =IF(BB79<>"",BB79*BA79,0) -> 180 | BE79: R-62 | BF79: 0000AXY16-AXY160104 | BG79: FY 2025-26 H2 Data | BH79: Consumption and RFS done in March 2026 but signoff done in April 2026
A80: =A79+1 -> 78 | B80: 0000AXY16-AXY160103 | C80: AXY16 | E80: AXY160103 | G80: Airtel | H80: DARIA | I80: Chandigarh | J80: Punjab | K80: Chandigarh | L80: AXY | M80: AXY | N80: 46112 | O80: 139 | P80: 46113 | Q80: 46125 | R80: 46113 | U80: Fresh | V80: 12F | W80: 139 | X80: 133 | Z80: PO awaited | AC80: 25.5 | AE80: 139 | AF80: UA | AG80: 12F | AH80: 12.5 | AI80: =IF(AE80<>"",AH80*AE80,0) -> 1737.5 | AK80: DROR Services Private Limited | AL80: 133 | AM80: 18 | AN80: =IF(AL80<>"",AM80*AL80,0) -> 2394 | AQ80: =IF(AO80<>"",AP80*AO80,0) -> 0 | AR80: =AQ80+AN80 -> 2394 | AT80: ET-PO-PUN-2604-0016 | AU80: 46141 | AV80: =AM80 -> 18 | AW80: =AV80*AL80 -> 2394 | AY80: DSHR/2026-27/130 | AZ80: 46153 | BA80: =AM80 -> 18 | BB80: =AL80 -> 133 | BC80: =IF(BB80<>"",BB80*BA80,0) -> 2394 | BE80: R-63 | BF80: 0000AXY16-AXY160103 | BG80: FY 2025-26 H2 Data | BH80: Consumption and RFS done in March 2026 but signoff done in April 2026
A81: =A80+1 -> 79 | B81: 0000AXY16-AXY160107 | C81: AXY16 | E81: AXY160107 | G81: Airtel | H81: DARIA | I81: Chandigarh | J81: Punjab | K81: Chandigarh | L81: AXY | M81: AXY | N81: 46112 | O81: 133 | P81: 46113 | Q81: 46125 | R81: 46113 | U81: Fresh | V81: 12F | W81: 133 | X81: 127 | Z81: PO awaited | AC81: 25.5 | AE81: 133 | AF81: UA | AG81: 12F | AH81: 12.5 | AI81: =IF(AE81<>"",AH81*AE81,0) -> 1662.5 | AK81: DROR Services Private Limited | AL81: 127 | AM81: 18 | AN81: =IF(AL81<>"",AM81*AL81,0) -> 2286 | AQ81: =IF(AO81<>"",AP81*AO81,0) -> 0 | AR81: =AQ81+AN81 -> 2286 | AT81: ET-PO-PUN-2604-0016 | AU81: 46141 | AV81: =AM81 -> 18 | AW81: =AV81*AL81 -> 2286 | AY81: DSHR/2026-27/130 | AZ81: 46153 | BA81: =AM81 -> 18 | BB81: =AL81 -> 127 | BC81: =IF(BB81<>"",BB81*BA81,0) -> 2286 | BE81: R-64 | BF81: 0000AXY16-AXY160107 | BG81: FY 2025-26 H2 Data | BH81: Consumption and RFS done in March 2026 but signoff done in April 2026
A82: =A81+1 -> 80 | B82: 0000AXY16-AXY160108 | C82: AXY16 | E82: AXY160108 | G82: Airtel | H82: DARIA | I82: Chandigarh | J82: Punjab | K82: Chandigarh | L82: AXY | M82: AXY | N82: 46112 | O82: 68 | P82: 46113 | Q82: 46125 | R82: 46113 | U82: Fresh | V82: 12F | W82: 68 | X82: 66 | Z82: PO awaited | AC82: 25.5 | AE82: 68 | AF82: UA | AG82: 12F | AH82: 12.5 | AI82: =IF(AE82<>"",AH82*AE82,0) -> 850 | AK82: DROR Services Private Limited | AL82: 66 | AM82: 18 | AN82: =IF(AL82<>"",AM82*AL82,0) -> 1188 | AQ82: =IF(AO82<>"",AP82*AO82,0) -> 0 | AR82: =AQ82+AN82 -> 1188 | AT82: ET-PO-PUN-2604-0016 | AU82: 46141 | AV82: =AM82 -> 18 | AW82: =AV82*AL82 -> 1188 | AY82: DSHR/2026-27/130 | AZ82: 46153 | BA82: =AM82 -> 18 | BB82: =AL82 -> 66 | BC82: =IF(BB82<>"",BB82*BA82,0) -> 1188 | BE82: R-65 | BF82: 0000AXY16-AXY160108 | BG82: FY 2025-26 H2 Data | BH82: Consumption and RFS done in March 2026 but signoff done in April 2026
A83: =A82+1 -> 81 | B83: 0000AXY17-AXY170101 | C83: AXY17 | E83: AXY170101 | G83: Airtel | H83: DARIA | I83: Chandigarh | J83: Punjab | K83: Chandigarh | L83: AXY | M83: AXY | N83: 46112 | O83: 10 | P83: 46113 | Q83: 46125 | R83: 46113 | U83: Fresh | V83: 12F | W83: 10 | X83: 10 | Z83: PO awaited | AC83: 25.5 | AE83: 10 | AF83: UA | AG83: 12F | AH83: 12.5 | AI83: =IF(AE83<>"",AH83*AE83,0) -> 125 | AK83: DROR Services Private Limited | AL83: 10 | AM83: 18 | AN83: =IF(AL83<>"",AM83*AL83,0) -> 180 | AQ83: =IF(AO83<>"",AP83*AO83,0) -> 0 | AR83: =AQ83+AN83 -> 180 | AT83: ET-PO-PUN-2604-0016 | AU83: 46141 | AV83: =AM83 -> 18 | AW83: =AV83*AL83 -> 180 | AY83: DSHR/2026-27/130 | AZ83: 46153 | BA83: =AM83 -> 18 | BB83: =AL83 -> 10 | BC83: =IF(BB83<>"",BB83*BA83,0) -> 180 | BE83: R-66 | BF83: 0000AXY17-AXY170101 | BG83: FY 2025-26 H2 Data | BH83: Consumption and RFS done in March 2026 but signoff done in April 2026
A84: =A83+1 -> 82 | B84: 0000AXY17-AXY170107 | C84: AXY17 | E84: AXY170107 | G84: Airtel | H84: DARIA | I84: Chandigarh | J84: Punjab | K84: Chandigarh | L84: AXY | M84: AXY | N84: 46112 | O84: 91 | P84: 46113 | Q84: 46125 | R84: 46113 | U84: Fresh | V84: 24F | W84: 91 | X84: 91 | Z84: PO awaited | AC84: 30.5 | AE84: 91 | AF84: UA | AG84: 24F | AH84: 24.5 | AI84: =IF(AE84<>"",AH84*AE84,0) -> 2229.5 | AK84: DROR Services Private Limited | AL84: 91 | AM84: 18 | AN84: =IF(AL84<>"",AM84*AL84,0) -> 1638 | AQ84: =IF(AO84<>"",AP84*AO84,0) -> 0 | AR84: =AQ84+AN84 -> 1638 | AT84: ET-PO-PUN-2604-0016 | AU84: 46141 | AV84: =AM84 -> 18 | AW84: =AV84*AL84 -> 1638 | AY84: DSHR/2026-27/130 | AZ84: 46153 | BA84: =AM84 -> 18 | BB84: =AL84 -> 91 | BC84: =IF(BB84<>"",BB84*BA84,0) -> 1638 | BE84: R-67 | BF84: 0000AXY17-AXY170107 | BG84: FY 2025-26 H2 Data | BH84: Consumption and RFS done in March 2026 but signoff done in April 2026
A85: =A84+1 -> 83 | B85: 0000AXY17-AXY170201 | C85: AXY17 | E85: AXY170201 | G85: Airtel | H85: DARIA | I85: Chandigarh | J85: Punjab | K85: Chandigarh | L85: AXY | M85: AXY | N85: 46112 | O85: 110 | P85: 46113 | Q85: 46125 | R85: 46113 | U85: Fresh | V85: 12F | W85: 110 | X85: 104 | Z85: PO awaited | AC85: 25.5 | AE85: 110 | AF85: UA | AG85: 12F | AH85: 12.5 | AI85: =IF(AE85<>"",AH85*AE85,0) -> 1375 | AK85: DROR Services Private Limited | AL85: 104 | AM85: 18 | AN85: =IF(AL85<>"",AM85*AL85,0) -> 1872 | AQ85: =IF(AO85<>"",AP85*AO85,0) -> 0 | AR85: =AQ85+AN85 -> 1872 | AT85: ET-PO-PUN-2604-0016 | AU85: 46141 | AV85: =AM85 -> 18 | AW85: =AV85*AL85 -> 1872 | AY85: DSHR/2026-27/130 | AZ85: 46153 | BA85: =AM85 -> 18 | BB85: =AL85 -> 104 | BC85: =IF(BB85<>"",BB85*BA85,0) -> 1872 | BE85: R-69 | BF85: 0000AXY17-AXY170201 | BG85: FY 2025-26 H2 Data | BH85: Consumption and RFS done in March 2026 but signoff done in April 2026
...

Sheet Node Details
E1: =MATCH(E2,'Route-Details'!$B$2:$X$2,0) -> 6 | F1: =MATCH(F2,'Route-Details'!$B$2:$X$2,0) -> 7 | G1: =MATCH(G2,'Route-Details'!$B$2:$X$2,0) -> 8 | H1: =MATCH(H2,'Route-Details'!$B$2:$X$2,0) -> 9 | I1: =MATCH(I2,'Route-Details'!$B$2:$X$2,0) -> 11 | J1: =MATCH(J2,'Route-Details'!$B$2:$X$2,0) -> 12 | S1: =SUBTOTAL(9,S3:S1048576) -> 0
A2: Sr No | B2: FDC/FAT Unique ID (End Point) | C2: Latlong | D2: Route ID (Route on which FAT/FDC is connected) | E2: Customer | F2: Area Name | G2: City | H2: Telecom Circle | I2: OLT ID | J2: Cluster ID | K2: Online AT Date (Delivered) | L2: HOTO Date | M2: HOTO Signoff Date | N2: Start Date (Date from which we can bill) | O2: Lock-in Period | P2: Surrender Date | Q2: Any Additional Fiber used for connectivity | R2: Fiber Capacity | S2: Online AT Length (Delivered) | T2: OTDR length (in meters) | U2: Customer Billable length (in meters) | W2: Customer PO no | X2: PO length | Y2: PO Date | Z2: PO Rate | AB2: Fiber length deployed/used (in meters) | AC2: Fiber Type | AD2: Fiber Capacity | AE2: Fiber Rate per meter (incl Freight) | AF2: Fiber Material Cost | AH2: Execution Vendor Name | AI2: Vendor Billable Length (Fiber laying) | AJ2: Fiber Laying Rate | AK2: Fiber Laying/Execution Cost | AL2: OTM Length | AM2: OTM Execution Rate | AN2: OTM Cost | AO2: Total Vendor Cost | AQ2: Vendor PO No | AR2: Vendor PO Date | AS2: Vendor PO Rate | AT2: Vendor PO Cost | AV2: Vendor Invoice No | AW2: Vendor Invoice Date | AX2: Vendor Invoice Rate | AY2: Vendor Invoiced length | AZ2: Invoice Amt | BB2: Route no | BC2: Remark
A3: 1 | B3: AXZ01 | D3: 000000AXZ-0000AXZ01 | E3: =_xlfn.IFNA(VLOOKUP($D3,'Route-Details'!$B$2:$X$1048576,'Node Details'!E$1,0),"") -> Airtel | F3: =_xlfn.IFNA(VLOOKUP($D3,'Route-Details'!$B$2:$X$1048576,'Node Details'!F$1,0),"") -> DARIA | G3: =_xlfn.IFNA(VLOOKUP($D3,'Route-Details'!$B$2:$X$1048576,'Node Details'!G$1,0),"") -> Chandigarh | H3: =_xlfn.IFNA(VLOOKUP($D4,'Route-Details'!$B$2:$X$1048576,'Node Details'!H$1,0),"") -> Punjab | I3: =_xlfn.IFNA(VLOOKUP($D3,'Route-Details'!$B$2:$X$1048576,'Node Details'!I$1,0),"") -> AXZ | J3: =_xlfn.IFNA(VLOOKUP($D3,'Route-Details'!$B$2:$X$1048576,'Node Details'!J$1,0),"") -> AXZ | K3: 46110 | L3: 46110 | M3: 46119 | N3: 46110 | Q3: No | AF3: =IF(AB3<>"",AE3*AB3,0) -> 0 | AK3: =IF(AI3<>"",AJ3*AI3,0) -> 0 | AN3: =IF(AL3<>"",AM3*AL3,0) -> 0 | AO3: =AN3+AK3 -> 0 | AS3: =AJ3 -> 0 | AT3: =AS3*AI3 -> 0 | AX3: =AJ3 -> 0 | AY3: =AI3 -> 0 | AZ3: =IF(AY3<>"",AY3*AX3,0) -> 0 | BB3: R-1 | BC3: FY 2025-26 H2 Data
A4: =A3+1 -> 2 | B4: AXZ010101 | D4: 0000AXZ01-AXZ010101 | E4: =_xlfn.IFNA(VLOOKUP($D4,'Route-Details'!$B$2:$X$1048576,'Node Details'!E$1,0),"") -> Airtel | F4: =_xlfn.IFNA(VLOOKUP($D4,'Route-Details'!$B$2:$X$1048576,'Node Details'!F$1,0),"") -> DARIA | G4: =_xlfn.IFNA(VLOOKUP($D4,'Route-Details'!$B$2:$X$1048576,'Node Details'!G$1,0),"") -> Chandigarh | H4: =_xlfn.IFNA(VLOOKUP($D5,'Route-Details'!$B$2:$X$1048576,'Node Details'!H$1,0),"") -> Punjab | I4: =_xlfn.IFNA(VLOOKUP($D4,'Route-Details'!$B$2:$X$1048576,'Node Details'!I$1,0),"") -> AXZ | J4: =_xlfn.IFNA(VLOOKUP($D4,'Route-Details'!$B$2:$X$1048576,'Node Details'!J$1,0),"") -> AXZ | K4: 46110 | L4: 46110 | M4: 46119 | N4: 46110 | Q4: No | AF4: =IF(AB4<>"",AE4*AB4,0) -> 0 | AK4: =IF(AI4<>"",AJ4*AI4,0) -> 0 | AN4: =IF(AL4<>"",AM4*AL4,0) -> 0 | AO4: =AN4+AK4 -> 0 | AS4: =AJ4 -> 0 | AT4: =AS4*AI4 -> 0 | AX4: =AJ4 -> 0 | AY4: =AI4 -> 0 | AZ4: =IF(AY4<>"",AY4*AX4,0) -> 0 | BB4: R-3 | BC4: FY 2025-26 H2 Data
A5: =A4+1 -> 3 | B5: AXZ010102 | D5: 0000AXZ01-AXZ010102 | E5: =_xlfn.IFNA(VLOOKUP($D5,'Route-Details'!$B$2:$X$1048576,'Node Details'!E$1,0),"") -> Airtel | F5: =_xlfn.IFNA(VLOOKUP($D5,'Route-Details'!$B$2:$X$1048576,'Node Details'!F$1,0),"") -> DARIA | G5: =_xlfn.IFNA(VLOOKUP($D5,'Route-Details'!$B$2:$X$1048576,'Node Details'!G$1,0),"") -> Chandigarh | H5: =_xlfn.IFNA(VLOOKUP($D6,'Route-Details'!$B$2:$X$1048576,'Node Details'!H$1,0),"") -> Punjab | I5: =_xlfn.IFNA(VLOOKUP($D5,'Route-Details'!$B$2:$X$1048576,'Node Details'!I$1,0),"") -> AXZ | J5: =_xlfn.IFNA(VLOOKUP($D5,'Route-Details'!$B$2:$X$1048576,'Node Details'!J$1,0),"") -> AXZ | K5: 46110 | L5: 46110 | M5: 46119 | N5: 46110 | Q5: No | AF5: =IF(AB5<>"",AE5*AB5,0) -> 0 | AK5: =IF(AI5<>"",AJ5*AI5,0) -> 0 | AN5: =IF(AL5<>"",AM5*AL5,0) -> 0 | AO5: =AN5+AK5 -> 0 | AS5: =AJ5 -> 0 | AT5: =AS5*AI5 -> 0 | AX5: =AJ5 -> 0 | AY5: =AI5 -> 0 | AZ5: =IF(AY5<>"",AY5*AX5,0) -> 0 | BB5: R-4 | BC5: FY 2025-26 H2 Data
A6: =A5+1 -> 4 | B6: AXZ010103 | D6: 0000AXZ01-AXZ010105 | E6: =_xlfn.IFNA(VLOOKUP($D6,'Route-Details'!$B$2:$X$1048576,'Node Details'!E$1,0),"") -> Airtel | F6: =_xlfn.IFNA(VLOOKUP($D6,'Route-Details'!$B$2:$X$1048576,'Node Details'!F$1,0),"") -> DARIA | G6: =_xlfn.IFNA(VLOOKUP($D6,'Route-Details'!$B$2:$X$1048576,'Node Details'!G$1,0),"") -> Chandigarh | H6: =_xlfn.IFNA(VLOOKUP($D7,'Route-Details'!$B$2:$X$1048576,'Node Details'!H$1,0),"") -> Punjab | I6: =_xlfn.IFNA(VLOOKUP($D6,'Route-Details'!$B$2:$X$1048576,'Node Details'!I$1,0),"") -> AXZ | J6: =_xlfn.IFNA(VLOOKUP($D6,'Route-Details'!$B$2:$X$1048576,'Node Details'!J$1,0),"") -> AXZ | K6: 46110 | L6: 46110 | M6: 46119 | N6: 46110 | Q6: No | AF6: =IF(AB6<>"",AE6*AB6,0) -> 0 | AK6: =IF(AI6<>"",AJ6*AI6,0) -> 0 | AN6: =IF(AL6<>"",AM6*AL6,0) -> 0 | AO6: =AN6+AK6 -> 0 | AS6: =AJ6 -> 0 | AT6: =AS6*AI6 -> 0 | AX6: =AJ6 -> 0 | AY6: =AI6 -> 0 | AZ6: =IF(AY6<>"",AY6*AX6,0) -> 0 | BB6: R-5 | BC6: FY 2025-26 H2 Data
A7: =A6+1 -> 5 | B7: AXZ010104 | D7: 0000AXZ01-AXZ010105 | E7: =_xlfn.IFNA(VLOOKUP($D7,'Route-Details'!$B$2:$X$1048576,'Node Details'!E$1,0),"") -> Airtel | F7: =_xlfn.IFNA(VLOOKUP($D7,'Route-Details'!$B$2:$X$1048576,'Node Details'!F$1,0),"") -> DARIA | G7: =_xlfn.IFNA(VLOOKUP($D7,'Route-Details'!$B$2:$X$1048576,'Node Details'!G$1,0),"") -> Chandigarh | H7: =_xlfn.IFNA(VLOOKUP($D8,'Route-Details'!$B$2:$X$1048576,'Node Details'!H$1,0),"") -> Punjab | I7: =_xlfn.IFNA(VLOOKUP($D7,'Route-Details'!$B$2:$X$1048576,'Node Details'!I$1,0),"") -> AXZ | J7: =_xlfn.IFNA(VLOOKUP($D7,'Route-Details'!$B$2:$X$1048576,'Node Details'!J$1,0),"") -> AXZ | K7: 46110 | L7: 46110 | M7: 46119 | N7: 46110 | Q7: No | AF7: =IF(AB7<>"",AE7*AB7,0) -> 0 | AK7: =IF(AI7<>"",AJ7*AI7,0) -> 0 | AN7: =IF(AL7<>"",AM7*AL7,0) -> 0 | AO7: =AN7+AK7 -> 0 | AS7: =AJ7 -> 0 | AT7: =AS7*AI7 -> 0 | AX7: =AJ7 -> 0 | AY7: =AI7 -> 0 | AZ7: =IF(AY7<>"",AY7*AX7,0) -> 0 | BB7: R-5 | BC7: FY 2025-26 H2 Data
A8: =A7+1 -> 6 | B8: AXZ010105 | D8: 0000AXZ01-AXZ010105 | E8: =_xlfn.IFNA(VLOOKUP($D8,'Route-Details'!$B$2:$X$1048576,'Node Details'!E$1,0),"") -> Airtel | F8: =_xlfn.IFNA(VLOOKUP($D8,'Route-Details'!$B$2:$X$1048576,'Node Details'!F$1,0),"") -> DARIA | G8: =_xlfn.IFNA(VLOOKUP($D8,'Route-Details'!$B$2:$X$1048576,'Node Details'!G$1,0),"") -> Chandigarh | H8: =_xlfn.IFNA(VLOOKUP($D9,'Route-Details'!$B$2:$X$1048576,'Node Details'!H$1,0),"") -> Punjab | I8: =_xlfn.IFNA(VLOOKUP($D8,'Route-Details'!$B$2:$X$1048576,'Node Details'!I$1,0),"") -> AXZ | J8: =_xlfn.IFNA(VLOOKUP($D8,'Route-Details'!$B$2:$X$1048576,'Node Details'!J$1,0),"") -> AXZ | K8: 46110 | L8: 46110 | M8: 46119 | N8: 46110 | Q8: No | AF8: =IF(AB8<>"",AE8*AB8,0) -> 0 | AK8: =IF(AI8<>"",AJ8*AI8,0) -> 0 | AN8: =IF(AL8<>"",AM8*AL8,0) -> 0 | AO8: =AN8+AK8 -> 0 | AS8: =AJ8 -> 0 | AT8: =AS8*AI8 -> 0 | AX8: =AJ8 -> 0 | AY8: =AI8 -> 0 | AZ8: =IF(AY8<>"",AY8*AX8,0) -> 0 | BB8: R-5 | BC8: FY 2025-26 H2 Data
A9: =A8+1 -> 7 | B9: AXZ010106 | D9: 0000AXZ01-AXZ010202 | E9: =_xlfn.IFNA(VLOOKUP($D9,'Route-Details'!$B$2:$X$1048576,'Node Details'!E$1,0),"") -> Airtel | F9: =_xlfn.IFNA(VLOOKUP($D9,'Route-Details'!$B$2:$X$1048576,'Node Details'!F$1,0),"") -> DARIA | G9: =_xlfn.IFNA(VLOOKUP($D9,'Route-Details'!$B$2:$X$1048576,'Node Details'!G$1,0),"") -> Chandigarh | H9: =_xlfn.IFNA(VLOOKUP($D10,'Route-Details'!$B$2:$X$1048576,'Node Details'!H$1,0),"") -> Punjab | I9: =_xlfn.IFNA(VLOOKUP($D9,'Route-Details'!$B$2:$X$1048576,'Node Details'!I$1,0),"") -> AXZ | J9: =_xlfn.IFNA(VLOOKUP($D9,'Route-Details'!$B$2:$X$1048576,'Node Details'!J$1,0),"") -> AXZ | K9: 46110 | L9: 46110 | M9: 46119 | N9: 46110 | Q9: No | AF9: =IF(AB9<>"",AE9*AB9,0) -> 0 | AK9: =IF(AI9<>"",AJ9*AI9,0) -> 0 | AN9: =IF(AL9<>"",AM9*AL9,0) -> 0 | AO9: =AN9+AK9 -> 0 | AS9: =AJ9 -> 0 | AT9: =AS9*AI9 -> 0 | AX9: =AJ9 -> 0 | AY9: =AI9 -> 0 | AZ9: =IF(AY9<>"",AY9*AX9,0) -> 0 | BB9: R-6 | BC9: FY 2025-26 H2 Data
A10: =A9+1 -> 8 | B10: AXZ010107 | D10: 0000AXZ01-AXZ010202 | E10: =_xlfn.IFNA(VLOOKUP($D10,'Route-Details'!$B$2:$X$1048576,'Node Details'!E$1,0),"") -> Airtel | F10: =_xlfn.IFNA(VLOOKUP($D10,'Route-Details'!$B$2:$X$1048576,'Node Details'!F$1,0),"") -> DARIA | G10: =_xlfn.IFNA(VLOOKUP($D10,'Route-Details'!$B$2:$X$1048576,'Node Details'!G$1,0),"") -> Chandigarh | H10: =_xlfn.IFNA(VLOOKUP($D11,'Route-Details'!$B$2:$X$1048576,'Node Details'!H$1,0),"") -> Punjab | I10: =_xlfn.IFNA(VLOOKUP($D10,'Route-Details'!$B$2:$X$1048576,'Node Details'!I$1,0),"") -> AXZ | J10: =_xlfn.IFNA(VLOOKUP($D10,'Route-Details'!$B$2:$X$1048576,'Node Details'!J$1,0),"") -> AXZ | K10: 46110 | L10: 46110 | M10: 46119 | N10: 46110 | Q10: No | AF10: =IF(AB10<>"",AE10*AB10,0) -> 0 | AK10: =IF(AI10<>"",AJ10*AI10,0) -> 0 | AN10: =IF(AL10<>"",AM10*AL10,0) -> 0 | AO10: =AN10+AK10 -> 0 | AS10: =AJ10 -> 0 | AT10: =AS10*AI10 -> 0 | AX10: =AJ10 -> 0 | AY10: =AI10 -> 0 | AZ10: =IF(AY10<>"",AY10*AX10,0) -> 0 | BB10: R-6 | BC10: FY 2025-26 H2 Data
A11: =A10+1 -> 9 | B11: AXZ010108 | D11: 0000AXZ01-AXZ010202 | E11: =_xlfn.IFNA(VLOOKUP($D11,'Route-Details'!$B$2:$X$1048576,'Node Details'!E$1,0),"") -> Airtel | F11: =_xlfn.IFNA(VLOOKUP($D11,'Route-Details'!$B$2:$X$1048576,'Node Details'!F$1,0),"") -> DARIA | G11: =_xlfn.IFNA(VLOOKUP($D11,'Route-Details'!$B$2:$X$1048576,'Node Details'!G$1,0),"") -> Chandigarh | H11: =_xlfn.IFNA(VLOOKUP($D12,'Route-Details'!$B$2:$X$1048576,'Node Details'!H$1,0),"") -> Punjab | I11: =_xlfn.IFNA(VLOOKUP($D11,'Route-Details'!$B$2:$X$1048576,'Node Details'!I$1,0),"") -> AXZ | J11: =_xlfn.IFNA(VLOOKUP($D11,'Route-Details'!$B$2:$X$1048576,'Node Details'!J$1,0),"") -> AXZ | K11: 46110 | L11: 46110 | M11: 46119 | N11: 46110 | Q11: No | AF11: =IF(AB11<>"",AE11*AB11,0) -> 0 | AK11: =IF(AI11<>"",AJ11*AI11,0) -> 0 | AN11: =IF(AL11<>"",AM11*AL11,0) -> 0 | AO11: =AN11+AK11 -> 0 | AS11: =AJ11 -> 0 | AT11: =AS11*AI11 -> 0 | AX11: =AJ11 -> 0 | AY11: =AI11 -> 0 | AZ11: =IF(AY11<>"",AY11*AX11,0) -> 0 | BB11: R-6 | BC11: FY 2025-26 H2 Data
A12: =A11+1 -> 10 | B12: AXZ010201 | D12: 0000AXZ01-AXZ010202 | E12: =_xlfn.IFNA(VLOOKUP($D12,'Route-Details'!$B$2:$X$1048576,'Node Details'!E$1,0),"") -> Airtel | F12: =_xlfn.IFNA(VLOOKUP($D12,'Route-Details'!$B$2:$X$1048576,'Node Details'!F$1,0),"") -> DARIA | G12: =_xlfn.IFNA(VLOOKUP($D12,'Route-Details'!$B$2:$X$1048576,'Node Details'!G$1,0),"") -> Chandigarh | H12: =_xlfn.IFNA(VLOOKUP($D13,'Route-Details'!$B$2:$X$1048576,'Node Details'!H$1,0),"") -> Punjab | I12: =_xlfn.IFNA(VLOOKUP($D12,'Route-Details'!$B$2:$X$1048576,'Node Details'!I$1,0),"") -> AXZ | J12: =_xlfn.IFNA(VLOOKUP($D12,'Route-Details'!$B$2:$X$1048576,'Node Details'!J$1,0),"") -> AXZ | K12: 46110 | L12: 46110 | M12: 46119 | N12: 46110 | Q12: No | AF12: =IF(AB12<>"",AE12*AB12,0) -> 0 | AK12: =IF(AI12<>"",AJ12*AI12,0) -> 0 | AN12: =IF(AL12<>"",AM12*AL12,0) -> 0 | AO12: =AN12+AK12 -> 0 | AS12: =AJ12 -> 0 | AT12: =AS12*AI12 -> 0 | AX12: =AJ12 -> 0 | AY12: =AI12 -> 0 | AZ12: =IF(AY12<>"",AY12*AX12,0) -> 0 | BB12: R-6 | BC12: FY 2025-26 H2 Data
A13: =A12+1 -> 11 | B13: AXZ010202 | D13: 0000AXZ01-AXZ010202 | E13: =_xlfn.IFNA(VLOOKUP($D13,'Route-Details'!$B$2:$X$1048576,'Node Details'!E$1,0),"") -> Airtel | F13: =_xlfn.IFNA(VLOOKUP($D13,'Route-Details'!$B$2:$X$1048576,'Node Details'!F$1,0),"") -> DARIA | G13: =_xlfn.IFNA(VLOOKUP($D13,'Route-Details'!$B$2:$X$1048576,'Node Details'!G$1,0),"") -> Chandigarh | H13: =_xlfn.IFNA(VLOOKUP($D14,'Route-Details'!$B$2:$X$1048576,'Node Details'!H$1,0),"") -> Punjab | I13: =_xlfn.IFNA(VLOOKUP($D13,'Route-Details'!$B$2:$X$1048576,'Node Details'!I$1,0),"") -> AXZ | J13: =_xlfn.IFNA(VLOOKUP($D13,'Route-Details'!$B$2:$X$1048576,'Node Details'!J$1,0),"") -> AXZ | K13: 46110 | L13: 46110 | M13: 46119 | N13: 46110 | Q13: No | AF13: =IF(AB13<>"",AE13*AB13,0) -> 0 | AK13: =IF(AI13<>"",AJ13*AI13,0) -> 0 | AN13: =IF(AL13<>"",AM13*AL13,0) -> 0 | AO13: =AN13+AK13 -> 0 | AS13: =AJ13 -> 0 | AT13: =AS13*AI13 -> 0 | AX13: =AJ13 -> 0 | AY13: =AI13 -> 0 | AZ13: =IF(AY13<>"",AY13*AX13,0) -> 0 | BB13: R-6 | BC13: FY 2025-26 H2 Data
A14: =A13+1 -> 12 | B14: AXZ02 | D14: 000000AXZ-0000AXZ03 | E14: =_xlfn.IFNA(VLOOKUP($D14,'Route-Details'!$B$2:$X$1048576,'Node Details'!E$1,0),"") -> Airtel | F14: =_xlfn.IFNA(VLOOKUP($D14,'Route-Details'!$B$2:$X$1048576,'Node Details'!F$1,0),"") -> DARIA | G14: =_xlfn.IFNA(VLOOKUP($D14,'Route-Details'!$B$2:$X$1048576,'Node Details'!G$1,0),"") -> Chandigarh | H14: =_xlfn.IFNA(VLOOKUP($D15,'Route-Details'!$B$2:$X$1048576,'Node Details'!H$1,0),"") -> Punjab | I14: =_xlfn.IFNA(VLOOKUP($D14,'Route-Details'!$B$2:$X$1048576,'Node Details'!I$1,0),"") -> AXZ | J14: =_xlfn.IFNA(VLOOKUP($D14,'Route-Details'!$B$2:$X$1048576,'Node Details'!J$1,0),"") -> AXZ | K14: 46110 | L14: 46110 | M14: 46119 | N14: 46110 | Q14: No | AF14: =IF(AB14<>"",AE14*AB14,0) -> 0 | AK14: =IF(AI14<>"",AJ14*AI14,0) -> 0 | AN14: =IF(AL14<>"",AM14*AL14,0) -> 0 | AO14: =AN14+AK14 -> 0 | AS14: =AJ14 -> 0 | AT14: =AS14*AI14 -> 0 | AX14: =AJ14 -> 0 | AY14: =AI14 -> 0 | AZ14: =IF(AY14<>"",AY14*AX14,0) -> 0 | BB14: R-2 | BC14: FY 2025-26 H2 Data
A15: =A14+1 -> 13 | B15: AXZ020101 | D15: 0000AXZ02-AXZ020101 | E15: =_xlfn.IFNA(VLOOKUP($D15,'Route-Details'!$B$2:$X$1048576,'Node Details'!E$1,0),"") -> Airtel | F15: =_xlfn.IFNA(VLOOKUP($D15,'Route-Details'!$B$2:$X$1048576,'Node Details'!F$1,0),"") -> DARIA | G15: =_xlfn.IFNA(VLOOKUP($D15,'Route-Details'!$B$2:$X$1048576,'Node Details'!G$1,0),"") -> Chandigarh | H15: =_xlfn.IFNA(VLOOKUP($D16,'Route-Details'!$B$2:$X$1048576,'Node Details'!H$1,0),"") -> Punjab | I15: =_xlfn.IFNA(VLOOKUP($D15,'Route-Details'!$B$2:$X$1048576,'Node Details'!I$1,0),"") -> AXZ | J15: =_xlfn.IFNA(VLOOKUP($D15,'Route-Details'!$B$2:$X$1048576,'Node Details'!J$1,0),"") -> AXZ | K15: 46110 | L15: 46110 | M15: 46119 | N15: 46110 | Q15: No | AF15: =IF(AB15<>"",AE15*AB15,0) -> 0 | AK15: =IF(AI15<>"",AJ15*AI15,0) -> 0 | AN15: =IF(AL15<>"",AM15*AL15,0) -> 0 | AO15: =AN15+AK15 -> 0 | AS15: =AJ15 -> 0 | AT15: =AS15*AI15 -> 0 | AX15: =AJ15 -> 0 | AY15: =AI15 -> 0 | AZ15: =IF(AY15<>"",AY15*AX15,0) -> 0 | BB15: R-7 | BC15: FY 2025-26 H2 Data
... A40: =A39+1 -> 38 | B40: AXZ | D40: 000000AXZ-0000AXZ01 | E40: =_xlfn.IFNA(VLOOKUP($D40,'Route-Details'!$B$2:$X$1048576,'Node Details'!E$1,0),"") -> Airtel | F40: =_xlfn.IFNA(VLOOKUP($D40,'Route-Details'!$B$2:$X$1048576,'Node Details'!F$1,0),"") -> DARIA | G40: =_xlfn.IFNA(VLOOKUP($D40,'Route-Details'!$B$2:$X$1048576,'Node Details'!G$1,0),"") -> Chandigarh | H40: =_xlfn.IFNA(VLOOKUP($D41,'Route-Details'!$B$2:$X$1048576,'Node Details'!H$1,0),"") -> Punjab | I40: =_xlfn.IFNA(VLOOKUP($D40,'Route-Details'!$B$2:$X$1048576,'Node Details'!I$1,0),"") -> AXZ | J40: =_xlfn.IFNA(VLOOKUP($D40,'Route-Details'!$B$2:$X$1048576,'Node Details'!J$1,0),"") -> AXZ | K40: 46110 | L40: 46110 | M40: 46119 | N40: 46110 | Q40: No | AF40: =IF(AB40<>"",AE40*AB40,0) -> 0 | AK40: =IF(AI40<>"",AJ40*AI40,0) -> 0 | AN40: =IF(AL40<>"",AM40*AL40,0) -> 0 | AO40: =AN40+AK40 -> 0 | AS40: =AJ40 -> 0 | AT40: =AS40*AI40 -> 0 | AX40: =AJ40 -> 0 | AY40: =AI40 -> 0 | AZ40: =IF(AY40<>"",AY40*AX40,0) -> 0 | BB40: R-1 | BC40: FY 2025-26 H2 Data
A41: =A40+1 -> 39 | B41: AXY01 | D41: 000000AXY-0000AXY01 | E41: =_xlfn.IFNA(VLOOKUP($D41,'Route-Details'!$B$2:$X$1048576,'Node Details'!E$1,0),"") -> Airtel | F41: =_xlfn.IFNA(VLOOKUP($D41,'Route-Details'!$B$2:$X$1048576,'Node Details'!F$1,0),"") -> DARIA | G41: =_xlfn.IFNA(VLOOKUP($D41,'Route-Details'!$B$2:$X$1048576,'Node Details'!G$1,0),"") -> Chandigarh | H41: =_xlfn.IFNA(VLOOKUP($D42,'Route-Details'!$B$2:$X$1048576,'Node Details'!H$1,0),"") -> Punjab | I41: =_xlfn.IFNA(VLOOKUP($D41,'Route-Details'!$B$2:$X$1048576,'Node Details'!I$1,0),"") -> AXY | J41: =_xlfn.IFNA(VLOOKUP($D41,'Route-Details'!$B$2:$X$1048576,'Node Details'!J$1,0),"") -> AXY | K41: 46112 | L41: 46113 | M41: 46125 | N41: 46112 | Q41: No | BB41: R-3 | BC41: FY 2025-26 H2 Data
A42: =A41+1 -> 40 | B42: AXY010101 | D42: 0000AXY01-AXY010101 | E42: =_xlfn.IFNA(VLOOKUP($D42,'Route-Details'!$B$2:$X$1048576,'Node Details'!E$1,0),"") -> Airtel | F42: =_xlfn.IFNA(VLOOKUP($D42,'Route-Details'!$B$2:$X$1048576,'Node Details'!F$1,0),"") -> DARIA | G42: =_xlfn.IFNA(VLOOKUP($D42,'Route-Details'!$B$2:$X$1048576,'Node Details'!G$1,0),"") -> Chandigarh | H42: =_xlfn.IFNA(VLOOKUP($D43,'Route-Details'!$B$2:$X$1048576,'Node Details'!H$1,0),"") -> Punjab | I42: =_xlfn.IFNA(VLOOKUP($D42,'Route-Details'!$B$2:$X$1048576,'Node Details'!I$1,0),"") -> AXY | J42: =_xlfn.IFNA(VLOOKUP($D42,'Route-Details'!$B$2:$X$1048576,'Node Details'!J$1,0),"") -> AXY | K42: 46112 | L42: 46113 | M42: 46125 | N42: 46112 | Q42: No | BB42: R-6 | BC42: FY 2025-26 H2 Data
A43: =A42+1 -> 41 | B43: AXY010103 | D43: 0000AXY01-AXY010104 | E43: =_xlfn.IFNA(VLOOKUP($D43,'Route-Details'!$B$2:$X$1048576,'Node Details'!E$1,0),"") -> Airtel | F43: =_xlfn.IFNA(VLOOKUP($D43,'Route-Details'!$B$2:$X$1048576,'Node Details'!F$1,0),"") -> DARIA | G43: =_xlfn.IFNA(VLOOKUP($D43,'Route-Details'!$B$2:$X$1048576,'Node Details'!G$1,0),"") -> Chandigarh | H43: =_xlfn.IFNA(VLOOKUP($D44,'Route-Details'!$B$2:$X$1048576,'Node Details'!H$1,0),"") -> Punjab | I43: =_xlfn.IFNA(VLOOKUP($D43,'Route-Details'!$B$2:$X$1048576,'Node Details'!I$1,0),"") -> AXY | J43: =_xlfn.IFNA(VLOOKUP($D43,'Route-Details'!$B$2:$X$1048576,'Node Details'!J$1,0),"") -> AXY | K43: 46112 | L43: 46113 | M43: 46125 | N43: 46112 | Q43: No | BB43: R-7 | BC43: FY 2025-26 H2 Data
A44: =A43+1 -> 42 | B44: AXY010104 | D44: 0000AXY01-AXY010104 | E44: =_xlfn.IFNA(VLOOKUP($D44,'Route-Details'!$B$2:$X$1048576,'Node Details'!E$1,0),"") -> Airtel | F44: =_xlfn.IFNA(VLOOKUP($D44,'Route-Details'!$B$2:$X$1048576,'Node Details'!F$1,0),"") -> DARIA | G44: =_xlfn.IFNA(VLOOKUP($D44,'Route-Details'!$B$2:$X$1048576,'Node Details'!G$1,0),"") -> Chandigarh | H44: =_xlfn.IFNA(VLOOKUP($D45,'Route-Details'!$B$2:$X$1048576,'Node Details'!H$1,0),"") -> Punjab | I44: =_xlfn.IFNA(VLOOKUP($D44,'Route-Details'!$B$2:$X$1048576,'Node Details'!I$1,0),"") -> AXY | J44: =_xlfn.IFNA(VLOOKUP($D44,'Route-Details'!$B$2:$X$1048576,'Node Details'!J$1,0),"") -> AXY | K44: 46112 | L44: 46113 | M44: 46125 | N44: 46112 | Q44: No | BB44: R-7 | BC44: FY 2025-26 H2 Data
A45: =A44+1 -> 43 | B45: AXY010102 | D45: 0000AXY01-AXY010102 | E45: =_xlfn.IFNA(VLOOKUP($D45,'Route-Details'!$B$2:$X$1048576,'Node Details'!E$1,0),"") -> Airtel | F45: =_xlfn.IFNA(VLOOKUP($D45,'Route-Details'!$B$2:$X$1048576,'Node Details'!F$1,0),"") -> DARIA | G45: =_xlfn.IFNA(VLOOKUP($D45,'Route-Details'!$B$2:$X$1048576,'Node Details'!G$1,0),"") -> Chandigarh | H45: =_xlfn.IFNA(VLOOKUP($D46,'Route-Details'!$B$2:$X$1048576,'Node Details'!H$1,0),"") -> Punjab | I45: =_xlfn.IFNA(VLOOKUP($D45,'Route-Details'!$B$2:$X$1048576,'Node Details'!I$1,0),"") -> AXY | J45: =_xlfn.IFNA(VLOOKUP($D45,'Route-Details'!$B$2:$X$1048576,'Node Details'!J$1,0),"") -> AXY | K45: 46112 | L45: 46113 | M45: 46125 | N45: 46112 | Q45: No | BB45: R-8 | BC45: FY 2025-26 H2 Data
A46: =A45+1 -> 44 | B46: AXY03 | D46: 0000AXY02-0000AXY03 | E46: =_xlfn.IFNA(VLOOKUP($D46,'Route-Details'!$B$2:$X$1048576,'Node Details'!E$1,0),"") -> Airtel | F46: =_xlfn.IFNA(VLOOKUP($D46,'Route-Details'!$B$2:$X$1048576,'Node Details'!F$1,0),"") -> DARIA | G46: =_xlfn.IFNA(VLOOKUP($D46,'Route-Details'!$B$2:$X$1048576,'Node Details'!G$1,0),"") -> Chandigarh | H46: =_xlfn.IFNA(VLOOKUP($D47,'Route-Details'!$B$2:$X$1048576,'Node Details'!H$1,0),"") -> Punjab | I46: =_xlfn.IFNA(VLOOKUP($D46,'Route-Details'!$B$2:$X$1048576,'Node Details'!I$1,0),"") -> AXY | J46: =_xlfn.IFNA(VLOOKUP($D46,'Route-Details'!$B$2:$X$1048576,'Node Details'!J$1,0),"") -> AXY | K46: 46112 | L46: 46113 | M46: 46125 | N46: 46112 | Q46: No | BB46: R-5 | BC46: FY 2025-26 H2 Data
A47: =A46+1 -> 45 | B47: AXY030101 | D47: 0000AXY03-AXY030101 | E47: =_xlfn.IFNA(VLOOKUP($D47,'Route-Details'!$B$2:$X$1048576,'Node Details'!E$1,0),"") -> Airtel | F47: =_xlfn.IFNA(VLOOKUP($D47,'Route-Details'!$B$2:$X$1048576,'Node Details'!F$1,0),"") -> DARIA | G47: =_xlfn.IFNA(VLOOKUP($D47,'Route-Details'!$B$2:$X$1048576,'Node Details'!G$1,0),"") -> Chandigarh | H47: =_xlfn.IFNA(VLOOKUP($D48,'Route-Details'!$B$2:$X$1048576,'Node Details'!H$1,0),"") -> Punjab | I47: =_xlfn.IFNA(VLOOKUP($D47,'Route-Details'!$B$2:$X$1048576,'Node Details'!I$1,0),"") -> AXY | J47: =_xlfn.IFNA(VLOOKUP($D47,'Route-Details'!$B$2:$X$1048576,'Node Details'!J$1,0),"") -> AXY | K47: 46112 | L47: 46113 | M47: 46125 | N47: 46112 | Q47: No | BB47: R-9 | BC47: FY 2025-26 H2 Data
A48: =A47+1 -> 46 | B48: AXY030103 | D48: 0000AXY03-AXY030104 | E48: =_xlfn.IFNA(VLOOKUP($D48,'Route-Details'!$B$2:$X$1048576,'Node Details'!E$1,0),"") -> Airtel | F48: =_xlfn.IFNA(VLOOKUP($D48,'Route-Details'!$B$2:$X$1048576,'Node Details'!F$1,0),"") -> DARIA | G48: =_xlfn.IFNA(VLOOKUP($D48,'Route-Details'!$B$2:$X$1048576,'Node Details'!G$1,0),"") -> Chandigarh | H48: =_xlfn.IFNA(VLOOKUP($D49,'Route-Details'!$B$2:$X$1048576,'Node Details'!H$1,0),"") -> Punjab | I48: =_xlfn.IFNA(VLOOKUP($D48,'Route-Details'!$B$2:$X$1048576,'Node Details'!I$1,0),"") -> AXY | J48: =_xlfn.IFNA(VLOOKUP($D48,'Route-Details'!$B$2:$X$1048576,'Node Details'!J$1,0),"") -> AXY | K48: 46112 | L48: 46113 | M48: 46125 | N48: 46112 | Q48: No | BB48: R-10 | BC48: FY 2025-26 H2 Data
A49: =A48+1 -> 47 | B49: AXY030104 | D49: 0000AXY03-AXY030104 | E49: =_xlfn.IFNA(VLOOKUP($D49,'Route-Details'!$B$2:$X$1048576,'Node Details'!E$1,0),"") -> Airtel | F49: =_xlfn.IFNA(VLOOKUP($D49,'Route-Details'!$B$2:$X$1048576,'Node Details'!F$1,0),"") -> DARIA | G49: =_xlfn.IFNA(VLOOKUP($D49,'Route-Details'!$B$2:$X$1048576,'Node Details'!G$1,0),"") -> Chandigarh | H49: =_xlfn.IFNA(VLOOKUP($D50,'Route-Details'!$B$2:$X$1048576,'Node Details'!H$1,0),"") -> Punjab | I49: =_xlfn.IFNA(VLOOKUP($D49,'Route-Details'!$B$2:$X$1048576,'Node Details'!I$1,0),"") -> AXY | J49: =_xlfn.IFNA(VLOOKUP($D49,'Route-Details'!$B$2:$X$1048576,'Node Details'!J$1,0),"") -> AXY | K49: 46112 | L49: 46113 | M49: 46125 | N49: 46112 | Q49: No | BB49: R-10 | BC49: FY 2025-26 H2 Data
